Workbook

Sheet Sheet1
A1: 序号 | B1: 系列 | C1: 编码 | D1: 图号 | E1: 名称 | F1: 型号 | G1: 款数 | H1: 替代编码 | I1: 替代型号 | J1: 送检开始计划 | K1: 送检结束（获检验报告）计划 | L1: 中试开始计划 | M1: 中试结束计划 | N1: 批产开始计划 | O1: 批产结束计划 | P1: 上市 计划 | Q1: 送检开始 实际 | R1: 送检结束（获检验报告） 实际 | S1: 中试开始 实际 | T1: 中试结束 实际 | U1: 批产开始 实际 | V1: 批产结束 实际 | W1: 上市 实际 | X1: 获证实际 | Y1: 送检开始监控 | Z1: 送检结束监控 | AA1: 中试开始监控 | AB1: 中试结束监控 | AC1: 批产开始监控 | AD1: 批产结束监控 | AE1: 获证状态 | AF1: 上市状态 | AG1: 项目状态 | AH1: 监控标记 （0取消监控） | AI1: 备注 | AJ1: 产品复杂度 | AK1: 负责人 | AL1: 开发方式 | AM1: 产品当前阶段/状态 | AN1: 按计划下一步推进节点 | AO1: 新标实施日期 | AP1: 过渡期截至 （证书自动失效日期）
A2: 40 | B2: 工业消防 | C2: 19902049 | E2: 线型光束感烟火灾探测器（中科永安项目） | F2: JTY-VFD/SF-EI201(12mm) | G2: 1 | H2: - | I2: - | J2: 45868 | K2: 46011 | L2: 46022 | M2: =IF((L2+IF(AJ2="高",45,30))>P2,P2-30,L2+IF(AJ2="高",45,30)) -> 46052 | N2: =P2-IF(AJ2="高",50,30) -> 46083 | O2: =P2 -> 46113 | P2: 46113 | Q2: 45863 | R2: 46001 | S2: 46037 | X2: 46022 | Y2: {=_xlfn.SWITCH(TRUE,ISNUMBER(Q2)*Q2>J2,"逾期完成",ISNUMBER(Q2),"按期完成",J2>TODAY(),"待完成","逾期未完成")} -> 按期完成 | Z2: {=_xlfn.SWITCH(TRUE,ISNUMBER(R2)*R2>K2,"逾期完成",ISNUMBER(R2),"按期完成",K2>TODAY(),"待完成","逾期未完成")} -> 按期完成 | AA2: {=_xlfn.SWITCH(TRUE,ISNUMBER(S2)*S2>L2,"逾期完成",ISNUMBER(S2),"按期完成",L2>TODAY(),"待完成","逾期未完成")} -> 逾期完成 | AB2: {=_xlfn.SWITCH(TRUE,ISNUMBER(T2)*T2>M2,"逾期完成",ISNUMBER(T2),"按期完成",M2>TODAY(),"待完成","逾期未完成")} -> 逾期未完成 | AC2: {=_xlfn.SWITCH(TRUE,ISNUMBER(U2)*U2>N2,"逾期完成",ISNUMBER(U2),"按期完成",N2>TODAY(),"待完成","逾期未完成")} -> 逾期未完成 | AD2: {=_xlfn.SWITCH(TRUE,ISNUMBER(V2)*V2>O2,"逾期完成",ISNUMBER(V2),"按期完成",O2>TODAY(),"待完成","逾期未完成")} -> 逾期未完成 | AE2: =IF(ISNUMBER(X2),"已获证","未获证") -> 已获证 | AF2: {=_xlfn.SWITCH(TRUE,ISNUMBER(W2)*W2>P2,"逾期完成",ISNUMBER(W2),"按期完成",P2>TODAY(),"待完成","逾期未完成")} -> 逾期未完成 | AG2: 完成 | AJ2: 低 | AK2: 靳超 | AL2: 合作 | AM2: =IF(AND(OR(AB2="按期完成",AB2="逾期完成"),OR(AC2<>"待完成",AD2<>"待完成")),"批产,"&IF(OR(AC2="逾期完成",AC2="逾期未完成",AD2="逾期完成",AD2="逾期未完成"),"逾期","按期"),IF(AND(OR(Z2="按期完成",Z2="逾期完成"),OR(AA2<>"待完成",AB2<>"待完成")),"中试,"&IF(OR(AA2="逾期完成",AA2="逾期未完成",AB2="逾期完成",AB2="逾期未完成"),"逾期","按期"),IF(OR(Y2<>"待完成",Z2<>"待完成"),"送检,"&IF(OR(Y2="逾期完成",Y2="逾期未完成",Z2="逾期完成",Z2="逾期未完成"),"逾期","按期"),"未启动,未开始"))) -> 中试,逾期 | AN2: =IF(OR(NOT(ISNUMBER(J2)),NOT(ISNUMBER(L2)),NOT(ISNUMBER(M2)),NOT(ISNUMBER(N2)),NOT(ISNUMBER(O2)),NOT(ISNUMBER(P2))),"暂无计划",IF(ISBLANK(Q2),IF(AND(J2-TODAY()>=0,J2-TODAY()<=10),"⚠️ 送检开始（还有"&ROUNDUP(J2-TODAY(),0)&"天，重点关注）",IF(J2>=TODAY(),"送检开始（还有"&ROUNDUP(J2-TODAY(),0)&"天）","送检开始（已超期"&ROUNDUP(TODAY()-J2,0)&"天）")),IF(ISBLANK(S2),IF(AND(L2-TODAY()>=0,L2-TODAY()<=10),"⚠️ 中试开始（还有"&ROUNDUP(L2-TODAY(),0)&"天，重点关注）",IF(L2>=TODAY(),"中试开始（还有"&ROUNDUP(L2-TODAY(),0)&"天）","中试开始（已超期"&ROUNDUP(TODAY()-L2,0)&"天）")),IF(ISBLANK(T2),IF(AND(M2-TODAY()>=0,M2-TODAY()<=10),"⚠️ 中试结束（还有"&ROUNDUP(M2-TODAY(),0)&"天，重点关注）",IF(M2>=TODAY(),"中试结束（还有"&ROUNDUP(M2-TODAY(),0)&"天）","中试结束（已超期"&ROUNDUP(TODAY()-M2,0)&"天）")),IF(ISBLANK(U2),IF(AND(N2-TODAY()>=0,N2-TODAY()<=10),"⚠️ 批产开始（还有"&ROUNDUP(N2-TODAY(),0)&"天，重点关注）",IF(N2>=TODAY(),"批产开始（还有"&ROUNDUP(N2-TODAY(),0)&"天）","批产开始（已超期"&ROUNDUP(TODAY()-N2,0)&"天）")),IF(ISBLANK(V2),IF(AND(O2-TODAY()>=0,O2-TODAY()<=10),"⚠️ 批产结束（还有"&ROUNDUP(O2-TODAY(),0)&"天，重点关注）",IF(O2>=TODAY(),"批产结束（还有"&ROUNDUP(O2-TODAY(),0)&"天）","批产结束（已超期"&ROUNDUP(TODAY()-O2,0)&"天）")),IF(ISBLANK(W2),IF(AND(P2-TODAY()>=0,P2-TODAY()<=10),"⚠️ 上市（还有"&ROUNDUP(P2-TODAY(),0)&"天，重点关注）",IF(P2>=TODAY(),"上市（还有"&ROUNDUP(P2-TODAY(),0)&"天）","上市（已超期"&ROUNDUP(TODAY()-P2,0)&"天）")),"已完成所有阶段"))))))) -> 中试结束（已超期126天）
A3: 36 | B3: 工业消防 | C3: 11200349 | E3: 图像型火焰探测器（中科永安项目） | F3: VFD/SF-EI101(4mm) | G3: 1 | H3: - | I3: - | J3: 45868 | K3: 45960 | N3: =P3-IF(AJ3="高",50,30) -> 45993 | O3: =P3 -> 46023 | P3: 46023 | Q3: 45863 | R3: 45960 | S3: 45976 | T3: 46023 | U3: 46037 | V3: 46023 | W3: 46023 | X3: 45988 | Y3: {=_xlfn.SWITCH(TRUE,ISNUMBER(Q3)*Q3>J3,"逾期完成",ISNUMBER(Q3),"按期完成",J3>TODAY(),"待完成","逾期未完成")} -> 按期完成 | Z3: {=_xlfn.SWITCH(TRUE,ISNUMBER(R3)*R3>K3,"逾期完成",ISNUMBER(R3),"按期完成",K3>TODAY(),"待完成","逾期未完成")} -> 按期完成 | AA3: {=_xlfn.SWITCH(TRUE,ISNUMBER(S3)*S3>L3,"逾期完成",ISNUMBER(S3),"按期完成",L3>TODAY(),"待完成","逾期未完成")} -> 逾期完成 | AB3: {=_xlfn.SWITCH(TRUE,ISNUMBER(T3)*T3>M3,"逾期完成",ISNUMBER(T3),"按期完成",M3>TODAY(),"待完成","逾期未完成")} -> 逾期完成 | AC3: {=_xlfn.SWITCH(TRUE,ISNUMBER(U3)*U3>N3,"逾期完成",ISNUMBER(U3),"按期完成",N3>TODAY(),"待完成","逾期未完成")} -> 逾期完成 | AD3: {=_xlfn.SWITCH(TRUE,ISNUMBER(V3)*V3>O3,"逾期完成",ISNUMBER(V3),"按期完成",O3>TODAY(),"待完成","逾期未完成")} -> 按期完成 | AE3: =IF(ISNUMBER(X3),"已获证","未获证") -> 已获证 | AF3: {=_xlfn.SWITCH(TRUE,ISNUMBER(W3)*W3>P3,"逾期完成",ISNUMBER(W3),"按期完成",P3>TODAY(),"待完成","逾期未完成")} -> 按期完成 | AG3: 完成 | AH3: 0 | AJ3: 低 | AK3: 靳超 | AL3: 合作 | AM3: =IF(AND(OR(AB3="按期完成",AB3="逾期完成"),OR(AC3<>"待完成",AD3<>"待完成")),"批产,"&IF(OR(AC3="逾期完成",AC3="逾期未完成",AD3="逾期完成",AD3="逾期未完成"),"逾期","按期"),IF(AND(OR(Z3="按期完成",Z3="逾期完成"),OR(AA3<>"待完成",AB3<>"待完成")),"中试,"&IF(OR(AA3="逾期完成",AA3="逾期未完成",AB3="逾期完成",AB3="逾期未完成"),"逾期","按期"),IF(OR(Y3<>"待完成",Z3<>"待完成"),"送检,"&IF(OR(Y3="逾期完成",Y3="逾期未完成",Z3="逾期完成",Z3="逾期未完成"),"逾期","按期"),"未启动,未开始"))) -> 批产,逾期 | AN3: =IF(OR(NOT(ISNUMBER(J3)),NOT(ISNUMBER(L3)),NOT(ISNUMBER(M3)),NOT(ISNUMBER(N3)),NOT(ISNUMBER(O3)),NOT(ISNUMBER(P3))),"暂无计划",IF(ISBLANK(Q3),IF(AND(J3-TODAY()>=0,J3-TODAY()<=10),"⚠️ 送检开始（还有"&ROUNDUP(J3-TODAY(),0)&"天，重点关注）",IF(J3>=TODAY(),"送检开始（还有"&ROUNDUP(J3-TODAY(),0)&"天）","送检开始（已超期"&ROUNDUP(TODAY()-J3,0)&"天）")),IF(ISBLANK(S3),IF(AND(L3-TODAY()>=0,L3-TODAY()<=10),"⚠️ 中试开始（还有"&ROUNDUP(L3-TODAY(),0)&"天，重点关注）",IF(L3>=TODAY(),"中试开始（还有"&ROUNDUP(L3-TODAY(),0)&"天）","中试开始（已超期"&ROUNDUP(TODAY()-L3,0)&"天）")),IF(ISBLANK(T3),IF(AND(M3-TODAY()>=0,M3-TODAY()<=10),"⚠️ 中试结束（还有"&ROUNDUP(M3-TODAY(),0)&"天，重点关注）",IF(M3>=TODAY(),"中试结束（还有"&ROUNDUP(M3-TODAY(),0)&"天）","中试结束（已超期"&ROUNDUP(TODAY()-M3,0)&"天）")),IF(ISBLANK(U3),IF(AND(N3-TODAY()>=0,N3-TODAY()<=10),"⚠️ 批产开始（还有"&ROUNDUP(N3-TODAY(),0)&"天，重点关注）",IF(N3>=TODAY(),"批产开始（还有"&ROUNDUP(N3-TODAY(),0)&"天）","批产开始（已超期"&ROUNDUP(TODAY()-N3,0)&"天）")),IF(ISBLANK(V3),IF(AND(O3-TODAY()>=0,O3-TODAY()<=10),"⚠️ 批产结束（还有"&ROUNDUP(O3-TODAY(),0)&"天，重点关注）",IF(O3>=TODAY(),"批产结束（还有"&ROUNDUP(O3-TODAY(),0)&"天）","批产结束（已超期"&ROUNDUP(TODAY()-O3,0)&"天）")),IF(ISBLANK(W3),IF(AND(P3-TODAY()>=0,P3-TODAY()<=10),"⚠️ 上市（还有"&ROUNDUP(P3-TODAY(),0)&"天，重点关注）",IF(P3>=TODAY(),"上市（还有"&ROUNDUP(P3-TODAY(),0)&"天）","上市（已超期"&ROUNDUP(TODAY()-P3,0)&"天）")),"已完成所有阶段"))))))) -> 暂无计划
A4: 37 | B4: 工业消防 | C4: 11200348 | E4: 图像型火焰探测器（中科永安项目） | F4: VFD/SF-EI101(6mm) | G4: 1 | H4: - | I4: - | J4: 45868 | K4: 45960 | N4: =P4-IF(AJ4="高",50,30) -> 45993 | O4: =P4 -> 46023 | P4: 46023 | Q4: 45863 | R4: 45960 | S4: 45976 | T4: 46023 | U4: 46037 | V4: 46023 | W4: 46023 | X4: 45988 | Y4: {=_xlfn.SWITCH(TRUE,ISNUMBER(Q4)*Q4>J4,"逾期完成",ISNUMBER(Q4),"按期完成",J4>TODAY(),"待完成","逾期未完成")} -> 按期完成 | Z4: {=_xlfn.SWITCH(TRUE,ISNUMBER(R4)*R4>K4,"逾期完成",ISNUMBER(R4),"按期完成",K4>TODAY(),"待完成","逾期未完成")} -> 按期完成 | AA4: {=_xlfn.SWITCH(TRUE,ISNUMBER(S4)*S4>L4,"逾期完成",ISNUMBER(S4),"按期完成",L4>TODAY(),"待完成","逾期未完成")} -> 逾期完成 | AB4: {=_xlfn.SWITCH(TRUE,ISNUMBER(T4)*T4>M4,"逾期完成",ISNUMBER(T4),"按期完成",M4>TODAY(),"待完成","逾期未完成")} -> 逾期完成 | AC4: {=_xlfn.SWITCH(TRUE,ISNUMBER(U4)*U4>N4,"逾期完成",ISNUMBER(U4),"按期完成",N4>TODAY(),"待完成","逾期未完成")} -> 逾期完成 | AD4: {=_xlfn.SWITCH(TRUE,ISNUMBER(V4)*V4>O4,"逾期完成",ISNUMBER(V4),"按期完成",O4>TODAY(),"待完成","逾期未完成")} -> 按期完成 | AE4: =IF(ISNUMBER(X4),"已获证","未获证") -> 已获证 | AF4: {=_xlfn.SWITCH(TRUE,ISNUMBER(W4)*W4>P4,"逾期完成",ISNUMBER(W4),"按期完成",P4>TODAY(),"待完成","逾期未完成")} -> 按期完成 | AG4: 完成 | AH4: 0 | AJ4: 低 | AK4: 靳超 | AL4: 合作 | AM4: =IF(AND(OR(AB4="按期完成",AB4="逾期完成"),OR(AC4<>"待完成",AD4<>"待完成")),"批产,"&IF(OR(AC4="逾期完成",AC4="逾期未完成",AD4="逾期完成",AD4="逾期未完成"),"逾期","按期"),IF(AND(OR(Z4="按期完成",Z4="逾期完成"),OR(AA4<>"待完成",AB4<>"待完成")),"中试,"&IF(OR(AA4="逾期完成",AA4="逾期未完成",AB4="逾期完成",AB4="逾期未完成"),"逾期","按期"),IF(OR(Y4<>"待完成",Z4<>"待完成"),"送检,"&IF(OR(Y4="逾期完成",Y4="逾期未完成",Z4="逾期完成",Z4="逾期未完成"),"逾期","按期"),"未启动,未开始"))) -> 批产,逾期 | AN4: =IF(OR(NOT(ISNUMBER(J4)),NOT(ISNUMBER(L4)),NOT(ISNUMBER(M4)),NOT(ISNUMBER(N4)),NOT(ISNUMBER(O4)),NOT(ISNUMBER(P4))),"暂无计划",IF(ISBLANK(Q4),IF(AND(J4-TODAY()>=0,J4-TODAY()<=10),"⚠️ 送检开始（还有"&ROUNDUP(J4-TODAY(),0)&"天，重点关注）",IF(J4>=TODAY(),"送检开始（还有"&ROUNDUP(J4-TODAY(),0)&"天）","送检开始（已超期"&ROUNDUP(TODAY()-J4,0)&"天）")),IF(ISBLANK(S4),IF(AND(L4-TODAY()>=0,L4-TODAY()<=10),"⚠️ 中试开始（还有"&ROUNDUP(L4-TODAY(),0)&"天，重点关注）",IF(L4>=TODAY(),"中试开始（还有"&ROUNDUP(L4-TODAY(),0)&"天）","中试开始（已超期"&ROUNDUP(TODAY()-L4,0)&"天）")),IF(ISBLANK(T4),IF(AND(M4-TODAY()>=0,M4-TODAY()<=10),"⚠️ 中试结束（还有"&ROUNDUP(M4-TODAY(),0)&"天，重点关注）",IF(M4>=TODAY(),"中试结束（还有"&ROUNDUP(M4-TODAY(),0)&"天）","中试结束（已超期"&ROUNDUP(TODAY()-M4,0)&"天）")),IF(ISBLANK(U4),IF(AND(N4-TODAY()>=0,N4-TODAY()<=10),"⚠️ 批产开始（还有"&ROUNDUP(N4-TODAY(),0)&"天，重点关注）",IF(N4>=TODAY(),"批产开始（还有"&ROUNDUP(N4-TODAY(),0)&"天）","批产开始（已超期"&ROUNDUP(TODAY()-N4,0)&"天）")),IF(ISBLANK(V4),IF(AND(O4-TODAY()>=0,O4-TODAY()<=10),"⚠️ 批产结束（还有"&ROUNDUP(O4-TODAY(),0)&"天，重点关注）",IF(O4>=TODAY(),"批产结束（还有"&ROUNDUP(O4-TODAY(),0)&"天）","批产结束（已超期"&ROUNDUP(TODAY()-O4,0)&"天）")),IF(ISBLANK(W4),IF(AND(P4-TODAY()>=0,P4-TODAY()<=10),"⚠️ 上市（还有"&ROUNDUP(P4-TODAY(),0)&"天，重点关注）",IF(P4>=TODAY(),"上市（还有"&ROUNDUP(P4-TODAY(),0)&"天）","上市（已超期"&ROUNDUP(TODAY()-P4,0)&"天）")),"已完成所有阶段"))))))) -> 暂无计划
A5: 38 | B5: 工业消防 | C5: 11200347 | E5: 图像型火焰探测器（中科永安项目） | F5: VFD/SF-EI101(8mm) | G5: 1 | H5: - | I5: - | J5: 45868 | K5: 45960 | N5: =P5-IF(AJ5="高",50,30) -> 45993 | O5: =P5 -> 46023 | P5: 46023 | Q5: 45863 | R5: 45960 | S5: 45976 | T5: 46023 | U5: 46037 | V5: 46023 | W5: 46023 | X5: 45988 | Y5: {=_xlfn.SWITCH(TRUE,ISNUMBER(Q5)*Q5>J5,"逾期完成",ISNUMBER(Q5),"按期完成",J5>TODAY(),"待完成","逾期未完成")} -> 按期完成 | Z5: {=_xlfn.SWITCH(TRUE,ISNUMBER(R5)*R5>K5,"逾期完成",ISNUMBER(R5),"按期完成",K5>TODAY(),"待完成","逾期未完成")} -> 按期完成 | AA5: {=_xlfn.SWITCH(TRUE,ISNUMBER(S5)*S5>L5,"逾期完成",ISNUMBER(S5),"按期完成",L5>TODAY(),"待完成","逾期未完成")} -> 逾期完成 | AB5: {=_xlfn.SWITCH(TRUE,ISNUMBER(T5)*T5>M5,"逾期完成",ISNUMBER(T5),"按期完成",M5>TODAY(),"待完成","逾期未完成")} -> 逾期完成 | AC5: {=_xlfn.SWITCH(TRUE,ISNUMBER(U5)*U5>N5,"逾期完成",ISNUMBER(U5),"按期完成",N5>TODAY(),"待完成","逾期未完成")} -> 逾期完成 | AD5: {=_xlfn.SWITCH(TRUE,ISNUMBER(V5)*V5>O5,"逾期完成",ISNUMBER(V5),"按期完成",O5>TODAY(),"待完成","逾期未完成")} -> 按期完成 | AE5: =IF(ISNUMBER(X5),"已获证","未获证") -> 已获证 | AF5: {=_xlfn.SWITCH(TRUE,ISNUMBER(W5)*W5>P5,"逾期完成",ISNUMBER(W5),"按期完成",P5>TODAY(),"待完成","逾期未完成")} -> 按期完成 | AG5: 完成 | AH5: 0 | AJ5: 低 | AK5: 靳超 | AL5: 合作 | AM5: =IF(AND(OR(AB5="按期完成",AB5="逾期完成"),OR(AC5<>"待完成",AD5<>"待完成")),"批产,"&IF(OR(AC5="逾期完成",AC5="逾期未完成",AD5="逾期完成",AD5="逾期未完成"),"逾期","按期"),IF(AND(OR(Z5="按期完成",Z5="逾期完成"),OR(AA5<>"待完成",AB5<>"待完成")),"中试,"&IF(OR(AA5="逾期完成",AA5="逾期未完成",AB5="逾期完成",AB5="逾期未完成"),"逾期","按期"),IF(OR(Y5<>"待完成",Z5<>"待完成"),"送检,"&IF(OR(Y5="逾期完成",Y5="逾期未完成",Z5="逾期完成",Z5="逾期未完成"),"逾期","按期"),"未启动,未开始"))) -> 批产,逾期 | AN5: =IF(OR(NOT(ISNUMBER(J5)),NOT(ISNUMBER(L5)),NOT(ISNUMBER(M5)),NOT(ISNUMBER(N5)),NOT(ISNUMBER(O5)),NOT(ISNUMBER(P5))),"暂无计划",IF(ISBLANK(Q5),IF(AND(J5-TODAY()>=0,J5-TODAY()<=10),"⚠️ 送检开始（还有"&ROUNDUP(J5-TODAY(),0)&"天，重点关注）",IF(J5>=TODAY(),"送检开始（还有"&ROUNDUP(J5-TODAY(),0)&"天）","送检开始（已超期"&ROUNDUP(TODAY()-J5,0)&"天）")),IF(ISBLANK(S5),IF(AND(L5-TODAY()>=0,L5-TODAY()<=10),"⚠️ 中试开始（还有"&ROUNDUP(L5-TODAY(),0)&"天，重点关注）",IF(L5>=TODAY(),"中试开始（还有"&ROUNDUP(L5-TODAY(),0)&"天）","中试开始（已超期"&ROUNDUP(TODAY()-L5,0)&"天）")),IF(ISBLANK(T5),IF(AND(M5-TODAY()>=0,M5-TODAY()<=10),"⚠️ 中试结束（还有"&ROUNDUP(M5-TODAY(),0)&"天，重点关注）",IF(M5>=TODAY(),"中试结束（还有"&ROUNDUP(M5-TODAY(),0)&"天）","中试结束（已超期"&ROUNDUP(TODAY()-M5,0)&"天）")),IF(ISBLANK(U5),IF(AND(N5-TODAY()>=0,N5-TODAY()<=10),"⚠️ 批产开始（还有"&ROUNDUP(N5-TODAY(),0)&"天，重点关注）",IF(N5>=TODAY(),"批产开始（还有"&ROUNDUP(N5-TODAY(),0)&"天）","批产开始（已超期"&ROUNDUP(TODAY()-N5,0)&"天）")),IF(ISBLANK(V5),IF(AND(O5-TODAY()>=0,O5-TODAY()<=10),"⚠️ 批产结束（还有"&ROUNDUP(O5-TODAY(),0)&"天，重点关注）",IF(O5>=TODAY(),"批产结束（还有"&ROUNDUP(O5-TODAY(),0)&"天）","批产结束（已超期"&ROUNDUP(TODAY()-O5,0)&"天）")),IF(ISBLANK(W5),IF(AND(P5-TODAY()>=0,P5-TODAY()<=10),"⚠️ 上市（还有"&ROUNDUP(P5-TODAY(),0)&"天，重点关注）",IF(P5>=TODAY(),"上市（还有"&ROUNDUP(P5-TODAY(),0)&"天）","上市（已超期"&ROUNDUP(TODAY()-P5,0)&"天）")),"已完成所有阶段"))))))) -> 暂无计划
A6: 39 | B6: 工业消防 | C6: 11200346 | E6: 图像型火焰探测器（中科永安项目） | F6: VFD/SF-EI101(12mm) | G6: 1 | H6: - | I6: - | J6: 45868 | K6: 45960 | N6: =P6-IF(AJ6="高",50,30) -> 45993 | O6: =P6 -> 46023 | P6: 46023 | Q6: 45863 | R6: 45960 | S6: 45976 | T6: 46023 | U6: 46037 | V6: 46023 | W6: 46023 | X6: 45988 | Y6: {=_xlfn.SWITCH(TRUE,ISNUMBER(Q6)*Q6>J6,"逾期完成",ISNUMBER(Q6),"按期完成",J6>TODAY(),"待完成","逾期未完成")} -> 按期完成 | Z6: {=_xlfn.SWITCH(TRUE,ISNUMBER(R6)*R6>K6,"逾期完成",ISNUMBER(R6),"按期完成",K6>TODAY(),"待完成","逾期未完成")} -> 按期完成 | AA6: {=_xlfn.SWITCH(TRUE,ISNUMBER(S6)*S6>L6,"逾期完成",ISNUMBER(S6),"按期完成",L6>TODAY(),"待完成","逾期未完成")} -> 逾期完成 | AB6: {=_xlfn.SWITCH(TRUE,ISNUMBER(T6)*T6>M6,"逾期完成",ISNUMBER(T6),"按期完成",M6>TODAY(),"待完成","逾期未完成")} -> 逾期完成 | AC6: {=_xlfn.SWITCH(TRUE,ISNUMBER(U6)*U6>N6,"逾期完成",ISNUMBER(U6),"按期完成",N6>TODAY(),"待完成","逾期未完成")} -> 逾期完成 | AD6: {=_xlfn.SWITCH(TRUE,ISNUMBER(V6)*V6>O6,"逾期完成",ISNUMBER(V6),"按期完成",O6>TODAY(),"待完成","逾期未完成")} -> 按期完成 | AE6: =IF(ISNUMBER(X6),"已获证","未获证") -> 已获证 | AF6: {=_xlfn.SWITCH(TRUE,ISNUMBER(W6)*W6>P6,"逾期完成",ISNUMBER(W6),"按期完成",P6>TODAY(),"待完成","逾期未完成")} -> 按期完成 | AG6: 完成 | AH6: 0 | AJ6: 低 | AK6: 靳超 | AL6: 合作 | AM6: =IF(AND(OR(AB6="按期完成",AB6="逾期完成"),OR(AC6<>"待完成",AD6<>"待完成")),"批产,"&IF(OR(AC6="逾期完成",AC6="逾期未完成",AD6="逾期完成",AD6="逾期未完成"),"逾期","按期"),IF(AND(OR(Z6="按期完成",Z6="逾期完成"),OR(AA6<>"待完成",AB6<>"待完成")),"中试,"&IF(OR(AA6="逾期完成",AA6="逾期未完成",AB6="逾期完成",AB6="逾期未完成"),"逾期","按期"),IF(OR(Y6<>"待完成",Z6<>"待完成"),"送检,"&IF(OR(Y6="逾期完成",Y6="逾期未完成",Z6="逾期完成",Z6="逾期未完成"),"逾期","按期"),"未启动,未开始"))) -> 批产,逾期 | AN6: =IF(OR(NOT(ISNUMBER(J6)),NOT(ISNUMBER(L6)),NOT(ISNUMBER(M6)),NOT(ISNUMBER(N6)),NOT(ISNUMBER(O6)),NOT(ISNUMBER(P6))),"暂无计划",IF(ISBLANK(Q6),IF(AND(J6-TODAY()>=0,J6-TODAY()<=10),"⚠️ 送检开始（还有"&ROUNDUP(J6-TODAY(),0)&"天，重点关注）",IF(J6>=TODAY(),"送检开始（还有"&ROUNDUP(J6-TODAY(),0)&"天）","送检开始（已超期"&ROUNDUP(TODAY()-J6,0)&"天）")),IF(ISBLANK(S6),IF(AND(L6-TODAY()>=0,L6-TODAY()<=10),"⚠️ 中试开始（还有"&ROUNDUP(L6-TODAY(),0)&"天，重点关注）",IF(L6>=TODAY(),"中试开始（还有"&ROUNDUP(L6-TODAY(),0)&"天）","中试开始（已超期"&ROUNDUP(TODAY()-L6,0)&"天）")),IF(ISBLANK(T6),IF(AND(M6-TODAY()>=0,M6-TODAY()<=10),"⚠️ 中试结束（还有"&ROUNDUP(M6-TODAY(),0)&"天，重点关注）",IF(M6>=TODAY(),"中试结束（还有"&ROUNDUP(M6-TODAY(),0)&"天）","中试结束（已超期"&ROUNDUP(TODAY()-M6,0)&"天）")),IF(ISBLANK(U6),IF(AND(N6-TODAY()>=0,N6-TODAY()<=10),"⚠️ 批产开始（还有"&ROUNDUP(N6-TODAY(),0)&"天，重点关注）",IF(N6>=TODAY(),"批产开始（还有"&ROUNDUP(N6-TODAY(),0)&"天）","批产开始（已超期"&ROUNDUP(TODAY()-N6,0)&"天）")),IF(ISBLANK(V6),IF(AND(O6-TODAY()>=0,O6-TODAY()<=10),"⚠️ 批产结束（还有"&ROUNDUP(O6-TODAY(),0)&"天，重点关注）",IF(O6>=TODAY(),"批产结束（还有"&ROUNDUP(O6-TODAY(),0)&"天）","批产结束（已超期"&ROUNDUP(TODAY()-O6,0)&"天）")),IF(ISBLANK(W6),IF(AND(P6-TODAY()>=0,P6-TODAY()<=10),"⚠️ 上市（还有"&ROUNDUP(P6-TODAY(),0)&"天，重点关注）",IF(P6>=TODAY(),"上市（还有"&ROUNDUP(P6-TODAY(),0)&"天）","上市（已超期"&ROUNDUP(TODAY()-P6,0)&"天）")),"已完成所有阶段"))))))) -> 暂无计划
A7: 1 | B7: 火灾报警 | C7: 10101536 | E7: 点型光电感烟火灾探测器（本安型） | F7: JTY-GD-EI9012Ex | G7: 1 | H7: 10100811 | I7: JTY-GD-EI8017Ex | J7: 45899 | K7: =(MAX(J7,Q7)+60) -> 45959 | L7: =MAX(J7,Q7)+30 -> 45929 | M7: =IF((L7+IF(AJ7="高",45,30))>P7,P7-30,L7+IF(AJ7="高",45,30)) -> 45959 | N7: =P7-IF(AJ7="高",50,30) -> 46083 | O7: =P7 -> 46113 | P7: 46113 | Q7: 45869 | R7: 45971 | S7: 45953 | T7: 46111 | U7: 46051 | X7: 46020 | Y7: {=_xlfn.SWITCH(TRUE,ISNUMBER(Q7)*Q7>J7,"逾期完成",ISNUMBER(Q7),"按期完成",J7>TODAY(),"待完成","逾期未完成")} -> 按期完成 | Z7: {=_xlfn.SWITCH(TRUE,ISNUMBER(R7)*R7>K7,"逾期完成",ISNUMBER(R7),"按期完成",K7>TODAY(),"待完成","逾期未完成")} -> 逾期完成 | AA7: {=_xlfn.SWITCH(TRUE,ISNUMBER(S7)*S7>L7,"逾期完成",ISNUMBER(S7),"按期完成",L7>TODAY(),"待完成","逾期未完成")} -> 逾期完成 | AB7: {=_xlfn.SWITCH(TRUE,ISNUMBER(T7)*T7>M7,"逾期完成",ISNUMBER(T7),"按期完成",M7>TODAY(),"待完成","逾期未完成")} -> 逾期完成 | AC7: {=_xlfn.SWITCH(TRUE,ISNUMBER(U7)*U7>N7,"逾期完成",ISNUMBER(U7),"按期完成",N7>TODAY(),"待完成","逾期未完成")} -> 按期完成 | AD7: {=_xlfn.SWITCH(TRUE,ISNUMBER(V7)*V7>O7,"逾期完成",ISNUMBER(V7),"按期完成",O7>TODAY(),"待完成","逾期未完成")} -> 逾期未完成 | AE7: =IF(ISNUMBER(X7),"已获证","未获证") -> 已获证 | AF7: {=_xlfn.SWITCH(TRUE,ISNUMBER(W7)*W7>P7,"逾期完成",ISNUMBER(W7),"按期完成",P7>TODAY(),"待完成","逾期未完成")} -> 逾期未完成 | AG7: 完成 | AJ7: 低 | AK7: 崔景贺 | AL7: 自研 | AM7: =IF(AND(OR(AB7="按期完成",AB7="逾期完成"),OR(AC7<>"待完成",AD7<>"待完成")),"批产,"&IF(OR(AC7="逾期完成",AC7="逾期未完成",AD7="逾期完成",AD7="逾期未完成"),"逾期","按期"),IF(AND(OR(Z7="按期完成",Z7="逾期完成"),OR(AA7<>"待完成",AB7<>"待完成")),"中试,"&IF(OR(AA7="逾期完成",AA7="逾期未完成",AB7="逾期完成",AB7="逾期未完成"),"逾期","按期"),IF(OR(Y7<>"待完成",Z7<>"待完成"),"送检,"&IF(OR(Y7="逾期完成",Y7="逾期未完成",Z7="逾期完成",Z7="逾期未完成"),"逾期","按期"),"未启动,未开始"))) -> 批产,逾期 | AN7: =IF(OR(NOT(ISNUMBER(J7)),NOT(ISNUMBER(L7)),NOT(ISNUMBER(M7)),NOT(ISNUMBER(N7)),NOT(ISNUMBER(O7)),NOT(ISNUMBER(P7))),"暂无计划",IF(ISBLANK(Q7),IF(AND(J7-TODAY()>=0,J7-TODAY()<=10),"⚠️ 送检开始（还有"&ROUNDUP(J7-TODAY(),0)&"天，重点关注）",IF(J7>=TODAY(),"送检开始（还有"&ROUNDUP(J7-TODAY(),0)&"天）","送检开始（已超期"&ROUNDUP(TODAY()-J7,0)&"天）")),IF(ISBLANK(S7),IF(AND(L7-TODAY()>=0,L7-TODAY()<=10),"⚠️ 中试开始（还有"&ROUNDUP(L7-TODAY(),0)&"天，重点关注）",IF(L7>=TODAY(),"中试开始（还有"&ROUNDUP(L7-TODAY(),0)&"天）","中试开始（已超期"&ROUNDUP(TODAY()-L7,0)&"天）")),IF(ISBLANK(T7),IF(AND(M7-TODAY()>=0,M7-TODAY()<=10),"⚠️ 中试结束（还有"&ROUNDUP(M7-TODAY(),0)&"天，重点关注）",IF(M7>=TODAY(),"中试结束（还有"&ROUNDUP(M7-TODAY(),0)&"天）","中试结束（已超期"&ROUNDUP(TODAY()-M7,0)&"天）")),IF(ISBLANK(U7),IF(AND(N7-TODAY()>=0,N7-TODAY()<=10),"⚠️ 批产开始（还有"&ROUNDUP(N7-TODAY(),0)&"天，重点关注）",IF(N7>=TODAY(),"批产开始（还有"&ROUNDUP(N7-TODAY(),0)&"天）","批产开始（已超期"&ROUNDUP(TODAY()-N7,0)&"天）")),IF(ISBLANK(V7),IF(AND(O7-TODAY()>=0,O7-TODAY()<=10),"⚠️ 批产结束（还有"&ROUNDUP(O7-TODAY(),0)&"天，重点关注）",IF(O7>=TODAY(),"批产结束（还有"&ROUNDUP(O7-TODAY(),0)&"天）","批产结束（已超期"&ROUNDUP(TODAY()-O7,0)&"天）")),IF(ISBLANK(W7),IF(AND(P7-TODAY()>=0,P7-TODAY()<=10),"⚠️ 上市（还有"&ROUNDUP(P7-TODAY(),0)&"天，重点关注）",IF(P7>=TODAY(),"上市（还有"&ROUNDUP(P7-TODAY(),0)&"天）","上市（已超期"&ROUNDUP(TODAY()-P7,0)&"天）")),"已完成所有阶段"))))))) -> 批产结束（已超期65天） | AO7: 45778 | AP7: 46143
A8: 45 | B8: 气体灭火装置 | E8: 能美项目 | F8: 气体灭火装置（90、120、150） | G8: 3 | H8: - | I8: - | J8: 45899 | K8: =(MAX(J8,Q8)+60) -> 45971 | L8: 46063 | M8: 46101 | N8: 46101 | O8: =P8 -> 46101 | P8: 46101 | Q8: 45911 | R8: 46032 | X8: 46056 | Y8: {=_xlfn.SWITCH(TRUE,ISNUMBER(Q8)*Q8>J8,"逾期完成",ISNUMBER(Q8),"按期完成",J8>TODAY(),"待完成","逾期未完成")} -> 逾期完成 | Z8: {=_xlfn.SWITCH(TRUE,ISNUMBER(R8)*R8>K8,"逾期完成",ISNUMBER(R8),"按期完成",K8>TODAY(),"待完成","逾期未完成")} -> 逾期完成 | AA8: {=_xlfn.SWITCH(TRUE,ISNUMBER(S8)*S8>L8,"逾期完成",ISNUMBER(S8),"按期完成",L8>TODAY(),"待完成","逾期未完成")} -> 逾期未完成 | AB8: {=_xlfn.SWITCH(TRUE,ISNUMBER(T8)*T8>M8,"逾期完成",ISNUMBER(T8),"按期完成",M8>TODAY(),"待完成","逾期未完成")} -> 逾期未完成 | AC8: {=_xlfn.SWITCH(TRUE,ISNUMBER(U8)*U8>N8,"逾期完成",ISNUMBER(U8),"按期完成",N8>TODAY(),"待完成","逾期未完成")} -> 逾期未完成 | AD8: {=_xlfn.SWITCH(TRUE,ISNUMBER(V8)*V8>O8,"逾期完成",ISNUMBER(V8),"按期完成",O8>TODAY(),"待完成","逾期未完成")} -> 逾期未完成 | AE8: =IF(ISNUMBER(X8),"已获证","未获证") -> 已获证 | AF8: {=_xlfn.SWITCH(TRUE,ISNUMBER(W8)*W8>P8,"逾期完成",ISNUMBER(W8),"按期完成",P8>TODAY(),"待完成","逾期未完成")} -> 逾期未完成 | AG8: 完成 | AH8: 0 | AJ8: 低 | AK8: 赵朕波 | AL8: 合作 | AM8: =IF(AND(OR(AB8="按期完成",AB8="逾期完成"),OR(AC8<>"待完成",AD8<>"待完成")),"批产,"&IF(OR(AC8="逾期完成",AC8="逾期未完成",AD8="逾期完成",AD8="逾期未完成"),"逾期","按期"),IF(AND(OR(Z8="按期完成",Z8="逾期完成"),OR(AA8<>"待完成",AB8<>"待完成")),"中试,"&IF(OR(AA8="逾期完成",AA8="逾期未完成",AB8="逾期完成",AB8="逾期未完成"),"逾期","按期"),IF(OR(Y8<>"待完成",Z8<>"待完成"),"送检,"&IF(OR(Y8="逾期完成",Y8="逾期未完成",Z8="逾期完成",Z8="逾期未完成"),"逾期","按期"),"未启动,未开始"))) -> 中试,逾期 | AN8: =IF(OR(NOT(ISNUMBER(J8)),NOT(ISNUMBER(L8)),NOT(ISNUMBER(M8)),NOT(ISNUMBER(N8)),NOT(ISNUMBER(O8)),NOT(ISNUMBER(P8))),"暂无计划",IF(ISBLANK(Q8),IF(AND(J8-TODAY()>=0,J8-TODAY()<=10),"⚠️ 送检开始（还有"&ROUNDUP(J8-TODAY(),0)&"天，重点关注）",IF(J8>=TODAY(),"送检开始（还有"&ROUNDUP(J8-TODAY(),0)&"天）","送检开始（已超期"&ROUNDUP(TODAY()-J8,0)&"天）")),IF(ISBLANK(S8),IF(AND(L8-TODAY()>=0,L8-TODAY()<=10),"⚠️ 中试开始（还有"&ROUNDUP(L8-TODAY(),0)&"天，重点关注）",IF(L8>=TODAY(),"中试开始（还有"&ROUNDUP(L8-TODAY(),0)&"天）","中试开始（已超期"&ROUNDUP(TODAY()-L8,0)&"天）")),IF(ISBLANK(T8),IF(AND(M8-TODAY()>=0,M8-TODAY()<=10),"⚠️ 中试结束（还有"&ROUNDUP(M8-TODAY(),0)&"天，重点关注）",IF(M8>=TODAY(),"中试结束（还有"&ROUNDUP(M8-TODAY(),0)&"天）","中试结束（已超期"&ROUNDUP(TODAY()-M8,0)&"天）")),IF(ISBLANK(U8),IF(AND(N8-TODAY()>=0,N8-TODAY()<=10),"⚠️ 批产开始（还有"&ROUNDUP(N8-TODAY(),0)&"天，重点关注）",IF(N8>=TODAY(),"批产开始（还有"&ROUNDUP(N8-TODAY(),0)&"天）","批产开始（已超期"&ROUNDUP(TODAY()-N8,0)&"天）")),IF(ISBLANK(V8),IF(AND(O8-TODAY()>=0,O8-TODAY()<=10),"⚠️ 批产结束（还有"&ROUNDUP(O8-TODAY(),0)&"天，重点关注）",IF(O8>=TODAY(),"批产结束（还有"&ROUNDUP(O8-TODAY(),0)&"天）","批产结束（已超期"&ROUNDUP(TODAY()-O8,0)&"天）")),IF(ISBLANK(W8),IF(AND(P8-TODAY()>=0,P8-TODAY()<=10),"⚠️ 上市（还有"&ROUNDUP(P8-TODAY(),0)&"天，重点关注）",IF(P8>=TODAY(),"上市（还有"&ROUNDUP(P8-TODAY(),0)&"天）","上市（已超期"&ROUNDUP(TODAY()-P8,0)&"天）")),"已完成所有阶段"))))))) -> 中试开始（已超期115天） | AO8: 46204 | AP8: 46569
A9: 42 | B9: 火灾报警 | C9: 11200335 | E9: 线型光束感烟火灾探测器 | F9: JTY-HM-EI9019 | G9: 1 | H9: 10101104 | I9: JTY-HM-EI8019 | J9: 45920 | K9: =(MAX(J9,Q9)+60) -> 45980 | L9: 46096 | M9: =IF((L9+IF(AJ9="高",45,30))>P9,P9-30,L9+IF(AJ9="高",45,30)) -> 46141 | N9: =P9-IF(AJ9="高",50,30) -> 46153 | O9: =P9 -> 46203 | P9: 46203 | Q9: 45915 | R9: 46000 | S9: 46051 | T9: 46111 | X9: 46020 | Y9: {=_xlfn.SWITCH(TRUE,ISNUMBER(Q9)*Q9>J9,"逾期完成",ISNUMBER(Q9),"按期完成",J9>TODAY(),"待完成","逾期未完成")} -> 按期完成 | Z9: {=_xlfn.SWITCH(TRUE,ISNUMBER(R9)*R9>K9,"逾期完成",ISNUMBER(R9),"按期完成",K9>TODAY(),"待完成","逾期未完成")} -> 逾期完成 | AA9: {=_xlfn.SWITCH(TRUE,ISNUMBER(S9)*S9>L9,"逾期完成",ISNUMBER(S9),"按期完成",L9>TODAY(),"待完成","逾期未完成")} -> 按期完成 | AB9: {=_xlfn.SWITCH(TRUE,ISNUMBER(T9)*T9>M9,"逾期完成",ISNUMBER(T9),"按期完成",M9>TODAY(),"待完成","逾期未完成")} -> 按期完成 | AC9: {=_xlfn.SWITCH(TRUE,ISNUMBER(U9)*U9>N9,"逾期完成",ISNUMBER(U9),"按期完成",N9>TODAY(),"待完成","逾期未完成")} -> 逾期未完成 | AD9: {=_xlfn.SWITCH(TRUE,ISNUMBER(V9)*V9>O9,"逾期完成",ISNUMBER(V9),"按期完成",O9>TODAY(),"待完成","逾期未完成")} -> 待完成 | AE9: =IF(ISNUMBER(X9),"已获证","未获证") -> 已获证 | AF9: {=_xlfn.SWITCH(TRUE,ISNUMBER(W9)*W9>P9,"逾期完成",ISNUMBER(W9),"按期完成",P9>TODAY(),"待完成","逾期未完成")} -> 待完成 | AG9: 未完成 | AJ9: 高 | AK9: 韩振飞 | AL9: 自研 | AM9: =IF(AND(OR(AB9="按期完成",AB9="逾期完成"),OR(AC9<>"待完成",AD9<>"待完成")),"批产,"&IF(OR(AC9="逾期完成",AC9="逾期未完成",AD9="逾期完成",AD9="逾期未完成"),"逾期","按期"),IF(AND(OR(Z9="按期完成",Z9="逾期完成"),OR(AA9<>"待完成",AB9<>"待完成")),"中试,"&IF(OR(AA9="逾期完成",AA9="逾期未完成",AB9="逾期完成",AB9="逾期未完成"),"逾期","按期"),IF(OR(Y9<>"待完成",Z9<>"待完成"),"送检,"&IF(OR(Y9="逾期完成",Y9="逾期未完成",Z9="逾期完成",Z9="逾期未完成"),"逾期","按期"),"未启动,未开始"))) -> 批产,逾期 | AN9: =IF(OR(NOT(ISNUMBER(J9)),NOT(ISNUMBER(L9)),NOT(ISNUMBER(M9)),NOT(ISNUMBER(N9)),NOT(ISNUMBER(O9)),NOT(ISNUMBER(P9))),"暂无计划",IF(ISBLANK(Q9),IF(AND(J9-TODAY()>=0,J9-TODAY()<=10),"⚠️ 送检开始（还有"&ROUNDUP(J9-TODAY(),0)&"天，重点关注）",IF(J9>=TODAY(),"送检开始（还有"&ROUNDUP(J9-TODAY(),0)&"天）","送检开始（已超期"&ROUNDUP(TODAY()-J9,0)&"天）")),IF(ISBLANK(S9),IF(AND(L9-TODAY()>=0,L9-TODAY()<=10),"⚠️ 中试开始（还有"&ROUNDUP(L9-TODAY(),0)&"天，重点关注）",IF(L9>=TODAY(),"中试开始（还有"&ROUNDUP(L9-TODAY(),0)&"天）","中试开始（已超期"&ROUNDUP(TODAY()-L9,0)&"天）")),IF(ISBLANK(T9),IF(AND(M9-TODAY()>=0,M9-TODAY()<=10),"⚠️ 中试结束（还有"&ROUNDUP(M9-TODAY(),0)&"天，重点关注）",IF(M9>=TODAY(),"中试结束（还有"&ROUNDUP(M9-TODAY(),0)&"天）","中试结束（已超期"&ROUNDUP(TODAY()-M9,0)&"天）")),IF(ISBLANK(U9),IF(AND(N9-TODAY()>=0,N9-TODAY()<=10),"⚠️ 批产开始（还有"&ROUNDUP(N9-TODAY(),0)&"天，重点关注）",IF(N9>=TODAY(),"批产开始（还有"&ROUNDUP(N9-TODAY(),0)&"天）","批产开始（已超期"&ROUNDUP(TODAY()-N9,0)&"天）")),IF(ISBLANK(V9),IF(AND(O9-TODAY()>=0,O9-TODAY()<=10),"⚠️ 批产结束（还有"&ROUNDUP(O9-TODAY(),0)&"天，重点关注）",IF(O9>=TODAY(),"批产结束（还有"&ROUNDUP(O9-TODAY(),0)&"天）","批产结束（已超期"&ROUNDUP(TODAY()-O9,0)&"天）")),IF(ISBLANK(W9),IF(AND(P9-TODAY()>=0,P9-TODAY()<=10),"⚠️ 上市（还有"&ROUNDUP(P9-TODAY(),0)&"天，重点关注）",IF(P9>=TODAY(),"上市（还有"&ROUNDUP(P9-TODAY(),0)&"天）","上市（已超期"&ROUNDUP(TODAY()-P9,0)&"天）")),"已完成所有阶段"))))))) -> 批产开始（已超期25天）
A10: 4 | B10: 火灾报警 | C10: 10101998 | E10: 无线中继模块 | F10: J-EI9037W | G10: 1 | H10: 10101046 | I10: J-EI8037W | J10: 45930 | K10: 45991 | L10: 45981 | M10: 45991 | N10: 46022 | O10: =P10 -> 46143 | P10: 46143 | Q10: 45919 | R10: 45980 | S10: 45953 | T10: 46014 | X10: 46002 | Y10: {=_xlfn.SWITCH(TRUE,ISNUMBER(Q10)*Q10>J10,"逾期完成",ISNUMBER(Q10),"按期完成",J10>TODAY(),"待完成","逾期未完成")} -> 按期完成 | Z10: {=_xlfn.SWITCH(TRUE,ISNUMBER(R10)*R10>K10,"逾期完成",ISNUMBER(R10),"按期完成",K10>TODAY(),"待完成","逾期未完成")} -> 按期完成 | AA10: {=_xlfn.SWITCH(TRUE,ISNUMBER(S10)*S10>L10,"逾期完成",ISNUMBER(S10),"按期完成",L10>TODAY(),"待完成","逾期未完成")} -> 按期完成 | AB10: {=_xlfn.SWITCH(TRUE,ISNUMBER(T10)*T10>M10,"逾期完成",ISNUMBER(T10),"按期完成",M10>TODAY(),"待完成","逾期未完成")} -> 逾期完成 | AC10: {=_xlfn.SWITCH(TRUE,ISNUMBER(U10)*U10>N10,"逾期完成",ISNUMBER(U10),"按期完成",N10>TODAY(),"待完成","逾期未完成")} -> 逾期未完成 | AD10: {=_xlfn.SWITCH(TRUE,ISNUMBER(V10)*V10>O10,"逾期完成",ISNUMBER(V10),"按期完成",O10>TODAY(),"待完成","逾期未完成")} -> 逾期未完成 | AE10: =IF(ISNUMBER(X10),"已获证","未获证") -> 已获证 | AF10: {=_xlfn.SWITCH(TRUE,ISNUMBER(W10)*W10>P10,"逾期完成",ISNUMBER(W10),"按期完成",P10>TODAY(),"待完成","逾期未完成")} -> 逾期未完成 | AG10: 完成 | AI10: 设计变更未归档/4月8日归档 | AJ10: 高 | AK10: 胡明宇 | AL10: 自研 | AM10: =IF(AND(OR(AB10="按期完成",AB10="逾期完成"),OR(AC10<>"待完成",AD10<>"待完成")),"批产,"&IF(OR(AC10="逾期完成",AC10="逾期未完成",AD10="逾期完成",AD10="逾期未完成"),"逾期","按期"),IF(AND(OR(Z10="按期完成",Z10="逾期完成"),OR(AA10<>"待完成",AB10<>"待完成")),"中试,"&IF(OR(AA10="逾期完成",AA10="逾期未完成",AB10="逾期完成",AB10="逾期未完成"),"逾期","按期"),IF(OR(Y10<>"待完成",Z10<>"待完成"),"送检,"&IF(OR(Y10="逾期完成",Y10="逾期未完成",Z10="逾期完成",Z10="逾期未完成"),"逾期","按期"),"未启动,未开始"))) -> 批产,逾期 | AN10: =IF(OR(NOT(ISNUMBER(J10)),NOT(ISNUMBER(L10)),NOT(ISNUMBER(M10)),NOT(ISNUMBER(N10)),NOT(ISNUMBER(O10)),NOT(ISNUMBER(P10))),"暂无计划",IF(ISBLANK(Q10),IF(AND(J10-TODAY()>=0,J10-TODAY()<=10),"⚠️ 送检开始（还有"&ROUNDUP(J10-TODAY(),0)&"天，重点关注）",IF(J10>=TODAY(),"送检开始（还有"&ROUNDUP(J10-TODAY(),0)&"天）","送检开始（已超期"&ROUNDUP(TODAY()-J10,0)&"天）")),IF(ISBLANK(S10),IF(AND(L10-TODAY()>=0,L10-TODAY()<=10),"⚠️ 中试开始（还有"&ROUNDUP(L10-TODAY(),0)&"天，重点关注）",IF(L10>=TODAY(),"中试开始（还有"&ROUNDUP(L10-TODAY(),0)&"天）","中试开始（已超期"&ROUNDUP(TODAY()-L10,0)&"天）")),IF(ISBLANK(T10),IF(AND(M10-TODAY()>=0,M10-TODAY()<=10),"⚠️ 中试结束（还有"&ROUNDUP(M10-TODAY(),0)&"天，重点关注）",IF(M10>=TODAY(),"中试结束（还有"&ROUNDUP(M10-TODAY(),0)&"天）","中试结束（已超期"&ROUNDUP(TODAY()-M10,0)&"天）")),IF(ISBLANK(U10),IF(AND(N10-TODAY()>=0,N10-TODAY()<=10),"⚠️ 批产开始（还有"&ROUNDUP(N10-TODAY(),0)&"天，重点关注）",IF(N10>=TODAY(),"批产开始（还有"&ROUNDUP(N10-TODAY(),0)&"天）","批产开始（已超期"&ROUNDUP(TODAY()-N10,0)&"天）")),IF(ISBLANK(V10),IF(AND(O10-TODAY()>=0,O10-TODAY()<=10),"⚠️ 批产结束（还有"&ROUNDUP(O10-TODAY(),0)&"天，重点关注）",IF(O10>=TODAY(),"批产结束（还有"&ROUNDUP(O10-TODAY(),0)&"天）","批产结束（已超期"&ROUNDUP(TODAY()-O10,0)&"天）")),IF(ISBLANK(W10),IF(AND(P10-TODAY()>=0,P10-TODAY()<=10),"⚠️ 上市（还有"&ROUNDUP(P10-TODAY(),0)&"天，重点关注）",IF(P10>=TODAY(),"上市（还有"&ROUNDUP(P10-TODAY(),0)&"天）","上市（已超期"&ROUNDUP(TODAY()-P10,0)&"天）")),"已完成所有阶段"))))))) -> 批产开始（已超期156天）
A11: 35 | B11: 工业消防 | C11: 19902046 | E11: 点型红外火焰探测器（中科永安项目） | F11: JTG-IR3-EI301Ex | G11: 1 | H11: - | I11: - | J11: 45930 | K11: 45991 | L11: 46063 | M11: 46091 | N11: =P11-IF(AJ11="高",50,30) -> 46083 | O11: =P11 -> 46113 | P11: 46113 | Q11: 45904 | R11: 45981 | S11: 46063 | X11: 46057 | Y11: {=_xlfn.SWITCH(TRUE,ISNUMBER(Q11)*Q11>J11,"逾期完成",ISNUMBER(Q11),"按期完成",J11>TODAY(),"待完成","逾期未完成")} -> 按期完成 | Z11: {=_xlfn.SWITCH(TRUE,ISNUMBER(R11)*R11>K11,"逾期完成",ISNUMBER(R11),"按期完成",K11>TODAY(),"待完成","逾期未完成")} -> 按期完成 | AA11: {=_xlfn.SWITCH(TRUE,ISNUMBER(S11)*S11>L11,"逾期完成",ISNUMBER(S11),"按期完成",L11>TODAY(),"待完成","逾期未完成")} -> 按期完成 | AB11: {=_xlfn.SWITCH(TRUE,ISNUMBER(T11)*T11>M11,"逾期完成",ISNUMBER(T11),"按期完成",M11>TODAY(),"待完成","逾期未完成")} -> 逾期未完成 | AC11: {=_xlfn.SWITCH(TRUE,ISNUMBER(U11)*U11>N11,"逾期完成",ISNUMBER(U11),"按期完成",N11>TODAY(),"待完成","逾期未完成")} -> 逾期未完成 | AD11: {=_xlfn.SWITCH(TRUE,ISNUMBER(V11)*V11>O11,"逾期完成",ISNUMBER(V11),"按期完成",O11>TODAY(),"待完成","逾期未完成")} -> 逾期未完成 | AE11: =IF(ISNUMBER(X11),"已获证","未获证") -> 已获证 | AF11: {=_xlfn.SWITCH(TRUE,ISNUMBER(W11)*W11>P11,"逾期完成",ISNUMBER(W11),"按期完成",P11>TODAY(),"待完成","逾期未完成")} -> 逾期未完成 | AG11: 未完成 | AJ11: 低 | AK11: 靳超 | AL11: 合作 | AM11: =IF(AND(OR(AB11="按期完成",AB11="逾期完成"),OR(AC11<>"待完成",AD11<>"待完成")),"批产,"&IF(OR(AC11="逾期完成",AC11="逾期未完成",AD11="逾期完成",AD11="逾期未完成"),"逾期","按期"),IF(AND(OR(Z11="按期完成",Z11="逾期完成"),OR(AA11<>"待完成",AB11<>"待完成")),"中试,"&IF(OR(AA11="逾期完成",AA11="逾期未完成",AB11="逾期完成",AB11="逾期未完成"),"逾期","按期"),IF(OR(Y11<>"待完成",Z11<>"待完成"),"送检,"&IF(OR(Y11="逾期完成",Y11="逾期未完成",Z11="逾期完成",Z11="逾期未完成"),"逾期","按期"),"未启动,未开始"))) -> 中试,逾期 | AN11: =IF(OR(NOT(ISNUMBER(J11)),NOT(ISNUMBER(L11)),NOT(ISNUMBER(M11)),NOT(ISNUMBER(N11)),NOT(ISNUMBER(O11)),NOT(ISNUMBER(P11))),"暂无计划",IF(ISBLANK(Q11),IF(AND(J11-TODAY()>=0,J11-TODAY()<=10),"⚠️ 送检开始（还有"&ROUNDUP(J11-TODAY(),0)&"天，重点关注）",IF(J11>=TODAY(),"送检开始（还有"&ROUNDUP(J11-TODAY(),0)&"天）","送检开始（已超期"&ROUNDUP(TODAY()-J11,0)&"天）")),IF(ISBLANK(S11),IF(AND(L11-TODAY()>=0,L11-TODAY()<=10),"⚠️ 中试开始（还有"&ROUNDUP(L11-TODAY(),0)&"天，重点关注）",IF(L11>=TODAY(),"中试开始（还有"&ROUNDUP(L11-TODAY(),0)&"天）","中试开始（已超期"&ROUNDUP(TODAY()-L11,0)&"天）")),IF(ISBLANK(T11),IF(AND(M11-TODAY()>=0,M11-TODAY()<=10),"⚠️ 中试结束（还有"&ROUNDUP(M11-TODAY(),0)&"天，重点关注）",IF(M11>=TODAY(),"中试结束（还有"&ROUNDUP(M11-TODAY(),0)&"天）","中试结束（已超期"&ROUNDUP(TODAY()-M11,0)&"天）")),IF(ISBLANK(U11),IF(AND(N11-TODAY()>=0,N11-TODAY()<=10),"⚠️ 批产开始（还有"&ROUNDUP(N11-TODAY(),0)&"天，重点关注）",IF(N11>=TODAY(),"批产开始（还有"&ROUNDUP(N11-TODAY(),0)&"天）","批产开始（已超期"&ROUNDUP(TODAY()-N11,0)&"天）")),IF(ISBLANK(V11),IF(AND(O11-TODAY()>=0,O11-TODAY()<=10),"⚠️ 批产结束（还有"&ROUNDUP(O11-TODAY(),0)&"天，重点关注）",IF(O11>=TODAY(),"批产结束（还有"&ROUNDUP(O11-TODAY(),0)&"天）","批产结束（已超期"&ROUNDUP(TODAY()-O11,0)&"天）")),IF(ISBLANK(W11),IF(AND(P11-TODAY()>=0,P11-TODAY()<=10),"⚠️ 上市（还有"&ROUNDUP(P11-TODAY(),0)&"天，重点关注）",IF(P11>=TODAY(),"上市（还有"&ROUNDUP(P11-TODAY(),0)&"天）","上市（已超期"&ROUNDUP(TODAY()-P11,0)&"天）")),"已完成所有阶段"))))))) -> 中试结束（已超期87天） | AO11: 46327 | AP11: 46692
A12: 14 | B12: 特种消防 | C12: 10101455/ 10102008 | E12: 地铁FAS系统点型光电感烟火灾探测器 | F12: JTY-GD-EIN12/A | G12: 2 | H12: - | I12: - | J12: 45960 | K12: =(MAX(J12,Q12)+60) -> 46020 | L12: 46063 | M12: 46101 | N12: 46101 | O12: =P12 -> 46172 | P12: 46172 | Q12: 45853 | R12: 45971 | S12: 46007 | T12: 46122 | X12: 45996 | Y12: {=_xlfn.SWITCH(TRUE,ISNUMBER(Q12)*Q12>J12,"逾期完成",ISNUMBER(Q12),"按期完成",J12>TODAY(),"待完成","逾期未完成")} -> 按期完成 | Z12: {=_xlfn.SWITCH(TRUE,ISNUMBER(R12)*R12>K12,"逾期完成",ISNUMBER(R12),"按期完成",K12>TODAY(),"待完成","逾期未完成")} -> 按期完成 | AA12: {=_xlfn.SWITCH(TRUE,ISNUMBER(S12)*S12>L12,"逾期完成",ISNUMBER(S12),"按期完成",L12>TODAY(),"待完成","逾期未完成")} -> 按期完成 | AB12: {=_xlfn.SWITCH(TRUE,ISNUMBER(T12)*T12>M12,"逾期完成",ISNUMBER(T12),"按期完成",M12>TODAY(),"待完成","逾期未完成")} -> 逾期完成 | AC12: {=_xlfn.SWITCH(TRUE,ISNUMBER(U12)*U12>N12,"逾期完成",ISNUMBER(U12),"按期完成",N12>TODAY(),"待完成","逾期未完成")} -> 逾期未完成 | AD12: {=_xlfn.SWITCH(TRUE,ISNUMBER(V12)*V12>O12,"逾期完成",ISNUMBER(V12),"按期完成",O12>TODAY(),"待完成","逾期未完成")} -> 逾期未完成 | AE12: =IF(ISNUMBER(X12),"已获证","未获证") -> 已获证 | AF12: {=_xlfn.SWITCH(TRUE,ISNUMBER(W12)*W12>P12,"逾期完成",ISNUMBER(W12),"按期完成",P12>TODAY(),"待完成","逾期未完成")} -> 逾期未完成 | AG12: 未完成 | AJ12: 低 | AK12: 崔景贺 | AL12: 自研 | AM12: =IF(AND(OR(AB12="按期完成",AB12="逾期完成"),OR(AC12<>"待完成",AD12<>"待完成")),"批产,"&IF(OR(AC12="逾期完成",AC12="逾期未完成",AD12="逾期完成",AD12="逾期未完成"),"逾期","按期"),IF(AND(OR(Z12="按期完成",Z12="逾期完成"),OR(AA12<>"待完成",AB12<>"待完成")),"中试,"&IF(OR(AA12="逾期完成",AA12="逾期未完成",AB12="逾期完成",AB12="逾期未完成"),"逾期","按期"),IF(OR(Y12<>"待完成",Z12<>"待完成"),"送检,"&IF(OR(Y12="逾期完成",Y12="逾期未完成",Z12="逾期完成",Z12="逾期未完成"),"逾期","按期"),"未启动,未开始"))) -> 批产,逾期 | AN12: =IF(OR(NOT(ISNUMBER(J12)),NOT(ISNUMBER(L12)),NOT(ISNUMBER(M12)),NOT(ISNUMBER(N12)),NOT(ISNUMBER(O12)),NOT(ISNUMBER(P12))),"暂无计划",IF(ISBLANK(Q12),IF(AND(J12-TODAY()>=0,J12-TODAY()<=10),"⚠️ 送检开始（还有"&ROUNDUP(J12-TODAY(),0)&"天，重点关注）",IF(J12>=TODAY(),"送检开始（还有"&ROUNDUP(J12-TODAY(),0)&"天）","送检开始（已超期"&ROUNDUP(TODAY()-J12,0)&"天）")),IF(ISBLANK(S12),IF(AND(L12-TODAY()>=0,L12-TODAY()<=10),"⚠️ 中试开始（还有"&ROUNDUP(L12-TODAY(),0)&"天，重点关注）",IF(L12>=TODAY(),"中试开始（还有"&ROUNDUP(L12-TODAY(),0)&"天）","中试开始（已超期"&ROUNDUP(TODAY()-L12,0)&"天）")),IF(ISBLANK(T12),IF(AND(M12-TODAY()>=0,M12-TODAY()<=10),"⚠️ 中试结束（还有"&ROUNDUP(M12-TODAY(),0)&"天，重点关注）",IF(M12>=TODAY(),"中试结束（还有"&ROUNDUP(M12-TODAY(),0)&"天）","中试结束（已超期"&ROUNDUP(TODAY()-M12,0)&"天）")),IF(ISBLANK(U12),IF(AND(N12-TODAY()>=0,N12-TODAY()<=10),"⚠️ 批产开始（还有"&ROUNDUP(N12-TODAY(),0)&"天，重点关注）",IF(N12>=TODAY(),"批产开始（还有"&ROUNDUP(N12-TODAY(),0)&"天）","批产开始（已超期"&ROUNDUP(TODAY()-N12,0)&"天）")),IF(ISBLANK(V12),IF(AND(O12-TODAY()>=0,O12-TODAY()<=10),"⚠️ 批产结束（还有"&ROUNDUP(O12-TODAY(),0)&"天，重点关注）",IF(O12>=TODAY(),"批产结束（还有"&ROUNDUP(O12-TODAY(),0)&"天）","批产结束（已超期"&ROUNDUP(TODAY()-O12,0)&"天）")),IF(ISBLANK(W12),IF(AND(P12-TODAY()>=0,P12-TODAY()<=10),"⚠️ 上市（还有"&ROUNDUP(P12-TODAY(),0)&"天，重点关注）",IF(P12>=TODAY(),"上市（还有"&ROUNDUP(P12-TODAY(),0)&"天）","上市（已超期"&ROUNDUP(TODAY()-P12,0)&"天）")),"已完成所有阶段"))))))) -> 批产开始（已超期77天） | AO12: 45778 | AP12: 46143
A13: 16 | B13: 特种消防 | C13: 10101404 | E13: 地铁FAS系统手动火灾报警按钮 | F13: J-SAP-EIN21 | G13: 1 | H13: - | I13: - | J13: 45960 | K13: 46020 | L13: 46063 | M13: 46101 | N13: 46101 | O13: =P13 -> 46172 | P13: 46172 | Q13: 45958 | R13: 46044 | S13: 46051 | T13: 46115 | X13: 46083 | Y13: {=_xlfn.SWITCH(TRUE,ISNUMBER(Q13)*Q13>J13,"逾期完成",ISNUMBER(Q13),"按期完成",J13>TODAY(),"待完成","逾期未完成")} -> 按期完成 | Z13: {=_xlfn.SWITCH(TRUE,ISNUMBER(R13)*R13>K13,"逾期完成",ISNUMBER(R13),"按期完成",K13>TODAY(),"待完成","逾期未完成")} -> 逾期完成 | AA13: {=_xlfn.SWITCH(TRUE,ISNUMBER(S13)*S13>L13,"逾期完成",ISNUMBER(S13),"按期完成",L13>TODAY(),"待完成","逾期未完成")} -> 按期完成 | AB13: {=_xlfn.SWITCH(TRUE,ISNUMBER(T13)*T13>M13,"逾期完成",ISNUMBER(T13),"按期完成",M13>TODAY(),"待完成","逾期未完成")} -> 逾期完成 | AC13: {=_xlfn.SWITCH(TRUE,ISNUMBER(U13)*U13>N13,"逾期完成",ISNUMBER(U13),"按期完成",N13>TODAY(),"待完成","逾期未完成")} -> 逾期未完成 | AD13: {=_xlfn.SWITCH(TRUE,ISNUMBER(V13)*V13>O13,"逾期完成",ISNUMBER(V13),"按期完成",O13>TODAY(),"待完成","逾期未完成")} -> 逾期未完成 | AE13: =IF(ISNUMBER(X13),"已获证","未获证") -> 已获证 | AF13: {=_xlfn.SWITCH(TRUE,ISNUMBER(W13)*W13>P13,"逾期完成",ISNUMBER(W13),"按期完成",P13>TODAY(),"待完成","逾期未完成")} -> 逾期未完成 | AG13: 未完成 | AJ13: 低 | AK13: 胡双寒 | AL13: 自研 | AM13: =IF(AND(OR(AB13="按期完成",AB13="逾期完成"),OR(AC13<>"待完成",AD13<>"待完成")),"批产,"&IF(OR(AC13="逾期完成",AC13="逾期未完成",AD13="逾期完成",AD13="逾期未完成"),"逾期","按期"),IF(AND(OR(Z13="按期完成",Z13="逾期完成"),OR(AA13<>"待完成",AB13<>"待完成")),"中试,"&IF(OR(AA13="逾期完成",AA13="逾期未完成",AB13="逾期完成",AB13="逾期未完成"),"逾期","按期"),IF(OR(Y13<>"待完成",Z13<>"待完成"),"送检,"&IF(OR(Y13="逾期完成",Y13="逾期未完成",Z13="逾期完成",Z13="逾期未完成"),"逾期","按期"),"未启动,未开始"))) -> 批产,逾期 | AN13: =IF(OR(NOT(ISNUMBER(J13)),NOT(ISNUMBER(L13)),NOT(ISNUMBER(M13)),NOT(ISNUMBER(N13)),NOT(ISNUMBER(O13)),NOT(ISNUMBER(P13))),"暂无计划",IF(ISBLANK(Q13),IF(AND(J13-TODAY()>=0,J13-TODAY()<=10),"⚠️ 送检开始（还有"&ROUNDUP(J13-TODAY(),0)&"天，重点关注）",IF(J13>=TODAY(),"送检开始（还有"&ROUNDUP(J13-TODAY(),0)&"天）","送检开始（已超期"&ROUNDUP(TODAY()-J13,0)&"天）")),IF(ISBLANK(S13),IF(AND(L13-TODAY()>=0,L13-TODAY()<=10),"⚠️ 中试开始（还有"&ROUNDUP(L13-TODAY(),0)&"天，重点关注）",IF(L13>=TODAY(),"中试开始（还有"&ROUNDUP(L13-TODAY(),0)&"天）","中试开始（已超期"&ROUNDUP(TODAY()-L13,0)&"天）")),IF(ISBLANK(T13),IF(AND(M13-TODAY()>=0,M13-TODAY()<=10),"⚠️ 中试结束（还有"&ROUNDUP(M13-TODAY(),0)&"天，重点关注）",IF(M13>=TODAY(),"中试结束（还有"&ROUNDUP(M13-TODAY(),0)&"天）","中试结束（已超期"&ROUNDUP(TODAY()-M13,0)&"天）")),IF(ISBLANK(U13),IF(AND(N13-TODAY()>=0,N13-TODAY()<=10),"⚠️ 批产开始（还有"&ROUNDUP(N13-TODAY(),0)&"天，重点关注）",IF(N13>=TODAY(),"批产开始（还有"&ROUNDUP(N13-TODAY(),0)&"天）","批产开始（已超期"&ROUNDUP(TODAY()-N13,0)&"天）")),IF(ISBLANK(V13),IF(AND(O13-TODAY()>=0,O13-TODAY()<=10),"⚠️ 批产结束（还有"&ROUNDUP(O13-TODAY(),0)&"天，重点关注）",IF(O13>=TODAY(),"批产结束（还有"&ROUNDUP(O13-TODAY(),0)&"天）","批产结束（已超期"&ROUNDUP(TODAY()-O13,0)&"天）")),IF(ISBLANK(W13),IF(AND(P13-TODAY()>=0,P13-TODAY()<=10),"⚠️ 上市（还有"&ROUNDUP(P13-TODAY(),0)&"天，重点关注）",IF(P13>=TODAY(),"上市（还有"&ROUNDUP(P13-TODAY(),0)&"天）","上市（已超期"&ROUNDUP(TODAY()-P13,0)&"天）")),"已完成所有阶段"))))))) -> 批产开始（已超期77天） | AO13: 45992 | AP13: 46357
A14: 17 | B14: 特种消防 | C14: 10101407 | E14: 地铁FAS系统消火栓按钮 | F14: J-SAP-EIN24 | G14: 1 | H14: - | I14: - | J14: 45960 | K14: =(MAX(J14,Q14)+60) -> 46020 | L14: 46063 | M14: 46101 | N14: 46101 | O14: =P14 -> 46172 | P14: 46172 | Q14: 45958 | R14: 46020 | S14: 46051 | T14: 46115 | X14: 46056 | Y14: {=_xlfn.SWITCH(TRUE,ISNUMBER(Q14)*Q14>J14,"逾期完成",ISNUMBER(Q14),"按期完成",J14>TODAY(),"待完成","逾期未完成")} -> 按期完成 | Z14: {=_xlfn.SWITCH(TRUE,ISNUMBER(R14)*R14>K14,"逾期完成",ISNUMBER(R14),"按期完成",K14>TODAY(),"待完成","逾期未完成")} -> 按期完成 | AA14: {=_xlfn.SWITCH(TRUE,ISNUMBER(S14)*S14>L14,"逾期完成",ISNUMBER(S14),"按期完成",L14>TODAY(),"待完成","逾期未完成")} -> 按期完成 | AB14: {=_xlfn.SWITCH(TRUE,ISNUMBER(T14)*T14>M14,"逾期完成",ISNUMBER(T14),"按期完成",M14>TODAY(),"待完成","逾期未完成")} -> 逾期完成 | AC14: {=_xlfn.SWITCH(TRUE,ISNUMBER(U14)*U14>N14,"逾期完成",ISNUMBER(U14),"按期完成",N14>TODAY(),"待完成","逾期未完成")} -> 逾期未完成 | AD14: {=_xlfn.SWITCH(TRUE,ISNUMBER(V14)*V14>O14,"逾期完成",ISNUMBER(V14),"按期完成",O14>TODAY(),"待完成","逾期未完成")} -> 逾期未完成 | AE14: =IF(ISNUMBER(X14),"已获证","未获证") -> 已获证 | AF14: {=_xlfn.SWITCH(TRUE,ISNUMBER(W14)*W14>P14,"逾期完成",ISNUMBER(W14),"按期完成",P14>TODAY(),"待完成","逾期未完成")} -> 逾期未完成 | AG14: 未完成 | AJ14: 低 | AK14: 胡双寒 | AL14: 自研 | AM14: =IF(AND(OR(AB14="按期完成",AB14="逾期完成"),OR(AC14<>"待完成",AD14<>"待完成")),"批产,"&IF(OR(AC14="逾期完成",AC14="逾期未完成",AD14="逾期完成",AD14="逾期未完成"),"逾期","按期"),IF(AND(OR(Z14="按期完成",Z14="逾期完成"),OR(AA14<>"待完成",AB14<>"待完成")),"中试,"&IF(OR(AA14="逾期完成",AA14="逾期未完成",AB14="逾期完成",AB14="逾期未完成"),"逾期","按期"),IF(OR(Y14<>"待完成",Z14<>"待完成"),"送检,"&IF(OR(Y14="逾期完成",Y14="逾期未完成",Z14="逾期完成",Z14="逾期未完成"),"逾期","按期"),"未启动,未开始"))) -> 批产,逾期 | AN14: =IF(OR(NOT(ISNUMBER(J14)),NOT(ISNUMBER(L14)),NOT(ISNUMBER(M14)),NOT(ISNUMBER(N14)),NOT(ISNUMBER(O14)),NOT(ISNUMBER(P14))),"暂无计划",IF(ISBLANK(Q14),IF(AND(J14-TODAY()>=0,J14-TODAY()<=10),"⚠️ 送检开始（还有"&ROUNDUP(J14-TODAY(),0)&"天，重点关注）",IF(J14>=TODAY(),"送检开始（还有"&ROUNDUP(J14-TODAY(),0)&"天）","送检开始（已超期"&ROUNDUP(TODAY()-J14,0)&"天）")),IF(ISBLANK(S14),IF(AND(L14-TODAY()>=0,L14-TODAY()<=10),"⚠️ 中试开始（还有"&ROUNDUP(L14-TODAY(),0)&"天，重点关注）",IF(L14>=TODAY(),"中试开始（还有"&ROUNDUP(L14-TODAY(),0)&"天）","中试开始（已超期"&ROUNDUP(TODAY()-L14,0)&"天）")),IF(ISBLANK(T14),IF(AND(M14-TODAY()>=0,M14-TODAY()<=10),"⚠️ 中试结束（还有"&ROUNDUP(M14-TODAY(),0)&"天，重点关注）",IF(M14>=TODAY(),"中试结束（还有"&ROUNDUP(M14-TODAY(),0)&"天）","中试结束（已超期"&ROUNDUP(TODAY()-M14,0)&"天）")),IF(ISBLANK(U14),IF(AND(N14-TODAY()>=0,N14-TODAY()<=10),"⚠️ 批产开始（还有"&ROUNDUP(N14-TODAY(),0)&"天，重点关注）",IF(N14>=TODAY(),"批产开始（还有"&ROUNDUP(N14-TODAY(),0)&"天）","批产开始（已超期"&ROUNDUP(TODAY()-N14,0)&"天）")),IF(ISBLANK(V14),IF(AND(O14-TODAY()>=0,O14-TODAY()<=10),"⚠️ 批产结束（还有"&ROUNDUP(O14-TODAY(),0)&"天，重点关注）",IF(O14>=TODAY(),"批产结束（还有"&ROUNDUP(O14-TODAY(),0)&"天）","批产结束（已超期"&ROUNDUP(TODAY()-O14,0)&"天）")),IF(ISBLANK(W14),IF(AND(P14-TODAY()>=0,P14-TODAY()<=10),"⚠️ 上市（还有"&ROUNDUP(P14-TODAY(),0)&"天，重点关注）",IF(P14>=TODAY(),"上市（还有"&ROUNDUP(P14-TODAY(),0)&"天）","上市（已超期"&ROUNDUP(TODAY()-P14,0)&"天）")),"已完成所有阶段"))))))) -> 批产开始（已超期77天）
A15: 19 | B15: 特种消防 | C15: 10102015 | E15: 地铁FAS系统输入模块 | F15: J-EIN30 | G15: 1 | H15: - | I15: - | J15: 45960 | K15: =(MAX(J15,Q15)+60) -> 46020 | L15: 46063 | M15: 46101 | N15: 46101 | O15: =P15 -> 46172 | P15: 46172 | Q15: 45916 | R15: 45975 | S15: 46051 | T15: 46115 | X15: 46002 | Y15: {=_xlfn.SWITCH(TRUE,ISNUMBER(Q15)*Q15>J15,"逾期完成",ISNUMBER(Q15),"按期完成",J15>TODAY(),"待完成","逾期未完成")} -> 按期完成 | Z15: {=_xlfn.SWITCH(TRUE,ISNUMBER(R15)*R15>K15,"逾期完成",ISNUMBER(R15),"按期完成",K15>TODAY(),"待完成","逾期未完成")} -> 按期完成 | AA15: {=_xlfn.SWITCH(TRUE,ISNUMBER(S15)*S15>L15,"逾期完成",ISNUMBER(S15),"按期完成",L15>TODAY(),"待完成","逾期未完成")} -> 按期完成 | AB15: {=_xlfn.SWITCH(TRUE,ISNUMBER(T15)*T15>M15,"逾期完成",ISNUMBER(T15),"按期完成",M15>TODAY(),"待完成","逾期未完成")} -> 逾期完成 | AC15: {=_xlfn.SWITCH(TRUE,ISNUMBER(U15)*U15>N15,"逾期完成",ISNUMBER(U15),"按期完成",N15>TODAY(),"待完成","逾期未完成")} -> 逾期未完成 | AD15: {=_xlfn.SWITCH(TRUE,ISNUMBER(V15)*V15>O15,"逾期完成",ISNUMBER(V15),"按期完成",O15>TODAY(),"待完成","逾期未完成")} -> 逾期未完成 | AE15: =IF(ISNUMBER(X15),"已获证","未获证") -> 已获证 | AF15: {=_xlfn.SWITCH(TRUE,ISNUMBER(W15)*W15>P15,"逾期完成",ISNUMBER(W15),"按期完成",P15>TODAY(),"待完成","逾期未完成")} -> 逾期未完成 | AG15: 未完成 | AJ15: 低 | AK15: 潘荣誉 | AL15: 自研 | AM15: =IF(AND(OR(AB15="按期完成",AB15="逾期完成"),OR(AC15<>"待完成",AD15<>"待完成")),"批产,"&IF(OR(AC15="逾期完成",AC15="逾期未完成",AD15="逾期完成",AD15="逾期未完成"),"逾期","按期"),IF(AND(OR(Z15="按期完成",Z15="逾期完成"),OR(AA15<>"待完成",AB15<>"待完成")),"中试,"&IF(OR(AA15="逾期完成",AA15="逾期未完成",AB15="逾期完成",AB15="逾期未完成"),"逾期","按期"),IF(OR(Y15<>"待完成",Z15<>"待完成"),"送检,"&IF(OR(Y15="逾期完成",Y15="逾期未完成",Z15="逾期完成",Z15="逾期未完成"),"逾期","按期"),"未启动,未开始"))) -> 批产,逾期 | AN15: =IF(OR(NOT(ISNUMBER(J15)),NOT(ISNUMBER(L15)),NOT(ISNUMBER(M15)),NOT(ISNUMBER(N15)),NOT(ISNUMBER(O15)),NOT(ISNUMBER(P15))),"暂无计划",IF(ISBLANK(Q15),IF(AND(J15-TODAY()>=0,J15-TODAY()<=10),"⚠️ 送检开始（还有"&ROUNDUP(J15-TODAY(),0)&"天，重点关注）",IF(J15>=TODAY(),"送检开始（还有"&ROUNDUP(J15-TODAY(),0)&"天）","送检开始（已超期"&ROUNDUP(TODAY()-J15,0)&"天）")),IF(ISBLANK(S15),IF(AND(L15-TODAY()>=0,L15-TODAY()<=10),"⚠️ 中试开始（还有"&ROUNDUP(L15-TODAY(),0)&"天，重点关注）",IF(L15>=TODAY(),"中试开始（还有"&ROUNDUP(L15-TODAY(),0)&"天）","中试开始（已超期"&ROUNDUP(TODAY()-L15,0)&"天）")),IF(ISBLANK(T15),IF(AND(M15-TODAY()>=0,M15-TODAY()<=10),"⚠️ 中试结束（还有"&ROUNDUP(M15-TODAY(),0)&"天，重点关注）",IF(M15>=TODAY(),"中试结束（还有"&ROUNDUP(M15-TODAY(),0)&"天）","中试结束（已超期"&ROUNDUP(TODAY()-M15,0)&"天）")),IF(ISBLANK(U15),IF(AND(N15-TODAY()>=0,N15-TODAY()<=10),"⚠️ 批产开始（还有"&ROUNDUP(N15-TODAY(),0)&"天，重点关注）",IF(N15>=TODAY(),"批产开始（还有"&ROUNDUP(N15-TODAY(),0)&"天）","批产开始（已超期"&ROUNDUP(TODAY()-N15,0)&"天）")),IF(ISBLANK(V15),IF(AND(O15-TODAY()>=0,O15-TODAY()<=10),"⚠️ 批产结束（还有"&ROUNDUP(O15-TODAY(),0)&"天，重点关注）",IF(O15>=TODAY(),"批产结束（还有"&ROUNDUP(O15-TODAY(),0)&"天）","批产结束（已超期"&ROUNDUP(TODAY()-O15,0)&"天）")),IF(ISBLANK(W15),IF(AND(P15-TODAY()>=0,P15-TODAY()<=10),"⚠️ 上市（还有"&ROUNDUP(P15-TODAY(),0)&"天，重点关注）",IF(P15>=TODAY(),"上市（还有"&ROUNDUP(P15-TODAY(),0)&"天）","上市（已超期"&ROUNDUP(TODAY()-P15,0)&"天）")),"已完成所有阶段"))))))) -> 批产开始（已超期77天）
A16: 20 | B16: 特种消防 | C16: 10102016 | E16: 地铁FAS系统中继模块 | F16: J-EIN32 | G16: 1 | H16: - | I16: - | J16: 45960 | K16: =(MAX(J16,Q16)+60) -> 46020 | L16: 46063 | M16: 46101 | N16: 46101 | O16: =P16 -> 46172 | P16: 46172 | Q16: 45916 | R16: 45975 | S16: 46051 | T16: 46115 | X16: 46002 | Y16: {=_xlfn.SWITCH(TRUE,ISNUMBER(Q16)*Q16>J16,"逾期完成",ISNUMBER(Q16),"按期完成",J16>TODAY(),"待完成","逾期未完成")} -> 按期完成 | Z16: {=_xlfn.SWITCH(TRUE,ISNUMBER(R16)*R16>K16,"逾期完成",ISNUMBER(R16),"按期完成",K16>TODAY(),"待完成","逾期未完成")} -> 按期完成 | AA16: {=_xlfn.SWITCH(TRUE,ISNUMBER(S16)*S16>L16,"逾期完成",ISNUMBER(S16),"按期完成",L16>TODAY(),"待完成","逾期未完成")} -> 按期完成 | AB16: {=_xlfn.SWITCH(TRUE,ISNUMBER(T16)*T16>M16,"逾期完成",ISNUMBER(T16),"按期完成",M16>TODAY(),"待完成","逾期未完成")} -> 逾期完成 | AC16: {=_xlfn.SWITCH(TRUE,ISNUMBER(U16)*U16>N16,"逾期完成",ISNUMBER(U16),"按期完成",N16>TODAY(),"待完成","逾期未完成")} -> 逾期未完成 | AD16: {=_xlfn.SWITCH(TRUE,ISNUMBER(V16)*V16>O16,"逾期完成",ISNUMBER(V16),"按期完成",O16>TODAY(),"待完成","逾期未完成")} -> 逾期未完成 | AE16: =IF(ISNUMBER(X16),"已获证","未获证") -> 已获证 | AF16: {=_xlfn.SWITCH(TRUE,ISNUMBER(W16)*W16>P16,"逾期完成",ISNUMBER(W16),"按期完成",P16>TODAY(),"待完成","逾期未完成")} -> 逾期未完成 | AG16: 未完成 | AJ16: 低 | AK16: 潘荣誉 | AL16: 自研 | AM16: =IF(AND(OR(AB16="按期完成",AB16="逾期完成"),OR(AC16<>"待完成",AD16<>"待完成")),"批产,"&IF(OR(AC16="逾期完成",AC16="逾期未完成",AD16="逾期完成",AD16="逾期未完成"),"逾期","按期"),IF(AND(OR(Z16="按期完成",Z16="逾期完成"),OR(AA16<>"待完成",AB16<>"待完成")),"中试,"&IF(OR(AA16="逾期完成",AA16="逾期未完成",AB16="逾期完成",AB16="逾期未完成"),"逾期","按期"),IF(OR(Y16<>"待完成",Z16<>"待完成"),"送检,"&IF(OR(Y16="逾期完成",Y16="逾期未完成",Z16="逾期完成",Z16="逾期未完成"),"逾期","按期"),"未启动,未开始"))) -> 批产,逾期 | AN16: =IF(OR(NOT(ISNUMBER(J16)),NOT(ISNUMBER(L16)),NOT(ISNUMBER(M16)),NOT(ISNUMBER(N16)),NOT(ISNUMBER(O16)),NOT(ISNUMBER(P16))),"暂无计划",IF(ISBLANK(Q16),IF(AND(J16-TODAY()>=0,J16-TODAY()<=10),"⚠️ 送检开始（还有"&ROUNDUP(J16-TODAY(),0)&"天，重点关注）",IF(J16>=TODAY(),"送检开始（还有"&ROUNDUP(J16-TODAY(),0)&"天）","送检开始（已超期"&ROUNDUP(TODAY()-J16,0)&"天）")),IF(ISBLANK(S16),IF(AND(L16-TODAY()>=0,L16-TODAY()<=10),"⚠️ 中试开始（还有"&ROUNDUP(L16-TODAY(),0)&"天，重点关注）",IF(L16>=TODAY(),"中试开始（还有"&ROUNDUP(L16-TODAY(),0)&"天）","中试开始（已超期"&ROUNDUP(TODAY()-L16,0)&"天）")),IF(ISBLANK(T16),IF(AND(M16-TODAY()>=0,M16-TODAY()<=10),"⚠️ 中试结束（还有"&ROUNDUP(M16-TODAY(),0)&"天，重点关注）",IF(M16>=TODAY(),"中试结束（还有"&ROUNDUP(M16-TODAY(),0)&"天）","中试结束（已超期"&ROUNDUP(TODAY()-M16,0)&"天）")),IF(ISBLANK(U16),IF(AND(N16-TODAY()>=0,N16-TODAY()<=10),"⚠️ 批产开始（还有"&ROUNDUP(N16-TODAY(),0)&"天，重点关注）",IF(N16>=TODAY(),"批产开始（还有"&ROUNDUP(N16-TODAY(),0)&"天）","批产开始（已超期"&ROUNDUP(TODAY()-N16,0)&"天）")),IF(ISBLANK(V16),IF(AND(O16-TODAY()>=0,O16-TODAY()<=10),"⚠️ 批产结束（还有"&ROUNDUP(O16-TODAY(),0)&"天，重点关注）",IF(O16>=TODAY(),"批产结束（还有"&ROUNDUP(O16-TODAY(),0)&"天）","批产结束（已超期"&ROUNDUP(TODAY()-O16,0)&"天）")),IF(ISBLANK(W16),IF(AND(P16-TODAY()>=0,P16-TODAY()<=10),"⚠️ 上市（还有"&ROUNDUP(P16-TODAY(),0)&"天，重点关注）",IF(P16>=TODAY(),"上市（还有"&ROUNDUP(P16-TODAY(),0)&"天）","上市（已超期"&ROUNDUP(TODAY()-P16,0)&"天）")),"已完成所有阶段"))))))) -> 批产开始（已超期77天）
A17: 21 | B17: 特种消防 | C17: 10102017 | E17: 地铁FAS系统输入/输出模块 | F17: J-EIN41 | G17: 1 | H17: - | I17: - | J17: 45960 | K17: =(MAX(J17,Q17)+60) -> 46020 | L17: 46063 | M17: 46101 | N17: 46101 | O17: =P17 -> 46172 | P17: 46172 | Q17: 45916 | R17: 45975 | S17: 46051 | T17: 46115 | X17: 46002 | Y17: {=_xlfn.SWITCH(TRUE,ISNUMBER(Q17)*Q17>J17,"逾期完成",ISNUMBER(Q17),"按期完成",J17>TODAY(),"待完成","逾期未完成")} -> 按期完成 | Z17: {=_xlfn.SWITCH(TRUE,ISNUMBER(R17)*R17>K17,"逾期完成",ISNUMBER(R17),"按期完成",K17>TODAY(),"待完成","逾期未完成")} -> 按期完成 | AA17: {=_xlfn.SWITCH(TRUE,ISNUMBER(S17)*S17>L17,"逾期完成",ISNUMBER(S17),"按期完成",L17>TODAY(),"待完成","逾期未完成")} -> 按期完成 | AB17: {=_xlfn.SWITCH(TRUE,ISNUMBER(T17)*T17>M17,"逾期完成",ISNUMBER(T17),"按期完成",M17>TODAY(),"待完成","逾期未完成")} -> 逾期完成 | AC17: {=_xlfn.SWITCH(TRUE,ISNUMBER(U17)*U17>N17,"逾期完成",ISNUMBER(U17),"按期完成",N17>TODAY(),"待完成","逾期未完成")} -> 逾期未完成 | AD17: {=_xlfn.SWITCH(TRUE,ISNUMBER(V17)*V17>O17,"逾期完成",ISNUMBER(V17),"按期完成",O17>TODAY(),"待完成","逾期未完成")} -> 逾期未完成 | AE17: =IF(ISNUMBER(X17),"已获证","未获证") -> 已获证 | AF17: {=_xlfn.SWITCH(TRUE,ISNUMBER(W17)*W17>P17,"逾期完成",ISNUMBER(W17),"按期完成",P17>TODAY(),"待完成","逾期未完成")} -> 逾期未完成 | AG17: 未完成 | AJ17: 低 | AK17: 潘荣誉 | AL17: 自研 | AM17: =IF(AND(OR(AB17="按期完成",AB17="逾期完成"),OR(AC17<>"待完成",AD17<>"待完成")),"批产,"&IF(OR(AC17="逾期完成",AC17="逾期未完成",AD17="逾期完成",AD17="逾期未完成"),"逾期","按期"),IF(AND(OR(Z17="按期完成",Z17="逾期完成"),OR(AA17<>"待完成",AB17<>"待完成")),"中试,"&IF(OR(AA17="逾期完成",AA17="逾期未完成",AB17="逾期完成",AB17="逾期未完成"),"逾期","按期"),IF(OR(Y17<>"待完成",Z17<>"待完成"),"送检,"&IF(OR(Y17="逾期完成",Y17="逾期未完成",Z17="逾期完成",Z17="逾期未完成"),"逾期","按期"),"未启动,未开始"))) -> 批产,逾期 | AN17: =IF(OR(NOT(ISNUMBER(J17)),NOT(ISNUMBER(L17)),NOT(ISNUMBER(M17)),NOT(ISNUMBER(N17)),NOT(ISNUMBER(O17)),NOT(ISNUMBER(P17))),"暂无计划",IF(ISBLANK(Q17),IF(AND(J17-TODAY()>=0,J17-TODAY()<=10),"⚠️ 送检开始（还有"&ROUNDUP(J17-TODAY(),0)&"天，重点关注）",IF(J17>=TODAY(),"送检开始（还有"&ROUNDUP(J17-TODAY(),0)&"天）","送检开始（已超期"&ROUNDUP(TODAY()-J17,0)&"天）")),IF(ISBLANK(S17),IF(AND(L17-TODAY()>=0,L17-TODAY()<=10),"⚠️ 中试开始（还有"&ROUNDUP(L17-TODAY(),0)&"天，重点关注）",IF(L17>=TODAY(),"中试开始（还有"&ROUNDUP(L17-TODAY(),0)&"天）","中试开始（已超期"&ROUNDUP(TODAY()-L17,0)&"天）")),IF(ISBLANK(T17),IF(AND(M17-TODAY()>=0,M17-TODAY()<=10),"⚠️ 中试结束（还有"&ROUNDUP(M17-TODAY(),0)&"天，重点关注）",IF(M17>=TODAY(),"中试结束（还有"&ROUNDUP(M17-TODAY(),0)&"天）","中试结束（已超期"&ROUNDUP(TODAY()-M17,0)&"天）")),IF(ISBLANK(U17),IF(AND(N17-TODAY()>=0,N17-TODAY()<=10),"⚠️ 批产开始（还有"&ROUNDUP(N17-TODAY(),0)&"天，重点关注）",IF(N17>=TODAY(),"批产开始（还有"&ROUNDUP(N17-TODAY(),0)&"天）","批产开始（已超期"&ROUNDUP(TODAY()-N17,0)&"天）")),IF(ISBLANK(V17),IF(AND(O17-TODAY()>=0,O17-TODAY()<=10),"⚠️ 批产结束（还有"&ROUNDUP(O17-TODAY(),0)&"天，重点关注）",IF(O17>=TODAY(),"批产结束（还有"&ROUNDUP(O17-TODAY(),0)&"天）","批产结束（已超期"&ROUNDUP(TODAY()-O17,0)&"天）")),IF(ISBLANK(W17),IF(AND(P17-TODAY()>=0,P17-TODAY()<=10),"⚠️ 上市（还有"&ROUNDUP(P17-TODAY(),0)&"天，重点关注）",IF(P17>=TODAY(),"上市（还有"&ROUNDUP(P17-TODAY(),0)&"天）","上市（已超期"&ROUNDUP(TODAY()-P17,0)&"天）")),"已完成所有阶段"))))))) -> 批产开始（已超期77天）
A18: 22 | B18: 特种消防 | C18: 10102018 | E18: 地铁FAS系统输入/输出模块 | F18: J-EIN43 | G18: 1 | H18: - | I18: - | J18: 45960 | K18: =(MAX(J18,Q18)+60) -> 46020 | L18: 46063 | M18: 46101 | N18: 46101 | O18: =P18 -> 46172 | P18: 46172 | Q18: 45916 | R18: 45975 | S18: 46051 | T18: 46115 | X18: 46002 | Y18: {=_xlfn.SWITCH(TRUE,ISNUMBER(Q18)*Q18>J18,"逾期完成",ISNUMBER(Q18),"按期完成",J18>TODAY(),"待完成","逾期未完成")} -> 按期完成 | Z18: {=_xlfn.SWITCH(TRUE,ISNUMBER(R18)*R18>K18,"逾期完成",ISNUMBER(R18),"按期完成",K18>TODAY(),"待完成","逾期未完成")} -> 按期完成 | AA18: {=_xlfn.SWITCH(TRUE,ISNUMBER(S18)*S18>L18,"逾期完成",ISNUMBER(S18),"按期完成",L18>TODAY(),"待完成","逾期未完成")} -> 按期完成 | AB18: {=_xlfn.SWITCH(TRUE,ISNUMBER(T18)*T18>M18,"逾期完成",ISNUMBER(T18),"按期完成",M18>TODAY(),"待完成","逾期未完成")} -> 逾期完成 | AC18: {=_xlfn.SWITCH(TRUE,ISNUMBER(U18)*U18>N18,"逾期完成",ISNUMBER(U18),"按期完成",N18>TODAY(),"待完成","逾期未完成")} -> 逾期未完成 | AD18: {=_xlfn.SWITCH(TRUE,ISNUMBER(V18)*V18>O18,"逾期完成",ISNUMBER(V18),"按期完成",O18>TODAY(),"待完成","逾期未完成")} -> 逾期未完成 | AE18: =IF(ISNUMBER(X18),"已获证","未获证") -> 已获证 | AF18: {=_xlfn.SWITCH(TRUE,ISNUMBER(W18)*W18>P18,"逾期完成",ISNUMBER(W18),"按期完成",P18>TODAY(),"待完成","逾期未完成")} -> 逾期未完成 | AG18: 未完成 | AJ18: 低 | AK18: 潘荣誉 | AL18: 自研 | AM18: =IF(AND(OR(AB18="按期完成",AB18="逾期完成"),OR(AC18<>"待完成",AD18<>"待完成")),"批产,"&IF(OR(AC18="逾期完成",AC18="逾期未完成",AD18="逾期完成",AD18="逾期未完成"),"逾期","按期"),IF(AND(OR(Z18="按期完成",Z18="逾期完成"),OR(AA18<>"待完成",AB18<>"待完成")),"中试,"&IF(OR(AA18="逾期完成",AA18="逾期未完成",AB18="逾期完成",AB18="逾期未完成"),"逾期","按期"),IF(OR(Y18<>"待完成",Z18<>"待完成"),"送检,"&IF(OR(Y18="逾期完成",Y18="逾期未完成",Z18="逾期完成",Z18="逾期未完成"),"逾期","按期"),"未启动,未开始"))) -> 批产,逾期 | AN18: =IF(OR(NOT(ISNUMBER(J18)),NOT(ISNUMBER(L18)),NOT(ISNUMBER(M18)),NOT(ISNUMBER(N18)),NOT(ISNUMBER(O18)),NOT(ISNUMBER(P18))),"暂无计划",IF(ISBLANK(Q18),IF(AND(J18-TODAY()>=0,J18-TODAY()<=10),"⚠️ 送检开始（还有"&ROUNDUP(J18-TODAY(),0)&"天，重点关注）",IF(J18>=TODAY(),"送检开始（还有"&ROUNDUP(J18-TODAY(),0)&"天）","送检开始（已超期"&ROUNDUP(TODAY()-J18,0)&"天）")),IF(ISBLANK(S18),IF(AND(L18-TODAY()>=0,L18-TODAY()<=10),"⚠️ 中试开始（还有"&ROUNDUP(L18-TODAY(),0)&"天，重点关注）",IF(L18>=TODAY(),"中试开始（还有"&ROUNDUP(L18-TODAY(),0)&"天）","中试开始（已超期"&ROUNDUP(TODAY()-L18,0)&"天）")),IF(ISBLANK(T18),IF(AND(M18-TODAY()>=0,M18-TODAY()<=10),"⚠️ 中试结束（还有"&ROUNDUP(M18-TODAY(),0)&"天，重点关注）",IF(M18>=TODAY(),"中试结束（还有"&ROUNDUP(M18-TODAY(),0)&"天）","中试结束（已超期"&ROUNDUP(TODAY()-M18,0)&"天）")),IF(ISBLANK(U18),IF(AND(N18-TODAY()>=0,N18-TODAY()<=10),"⚠️ 批产开始（还有"&ROUNDUP(N18-TODAY(),0)&"天，重点关注）",IF(N18>=TODAY(),"批产开始（还有"&ROUNDUP(N18-TODAY(),0)&"天）","批产开始（已超期"&ROUNDUP(TODAY()-N18,0)&"天）")),IF(ISBLANK(V18),IF(AND(O18-TODAY()>=0,O18-TODAY()<=10),"⚠️ 批产结束（还有"&ROUNDUP(O18-TODAY(),0)&"天，重点关注）",IF(O18>=TODAY(),"批产结束（还有"&ROUNDUP(O18-TODAY(),0)&"天）","批产结束（已超期"&ROUNDUP(TODAY()-O18,0)&"天）")),IF(ISBLANK(W18),IF(AND(P18-TODAY()>=0,P18-TODAY()<=10),"⚠️ 上市（还有"&ROUNDUP(P18-TODAY(),0)&"天，重点关注）",IF(P18>=TODAY(),"上市（还有"&ROUNDUP(P18-TODAY(),0)&"天）","上市（已超期"&ROUNDUP(TODAY()-P18,0)&"天）")),"已完成所有阶段"))))))) -> 批产开始（已超期77天）
A19: 18 | B19: 特种消防 | C19: 10101401 | E19: 地铁FAS系统火灾声光警报器 | F19: J-EIN85 | G19: 1 | H19: - | I19: - | J19: 45960 | K19: =(MAX(J19,Q19)+60) -> 46063 | L19: 46063 | M19: 46101 | N19: 46101 | O19: =P19 -> 46172 | P19: 46172 | Q19: 46003 | R19: 46058 | S19: 46051 | T19: 46115 | X19: 45741 | Y19: {=_xlfn.SWITCH(TRUE,ISNUMBER(Q19)*Q19>J19,"逾期完成",ISNUMBER(Q19),"按期完成",J19>TODAY(),"待完成","逾期未完成")} -> 逾期完成 | Z19: {=_xlfn.SWITCH(TRUE,ISNUMBER(R19)*R19>K19,"逾期完成",ISNUMBER(R19),"按期完成",K19>TODAY(),"待完成","逾期未完成")} -> 按期完成 | AA19: {=_xlfn.SWITCH(TRUE,ISNUMBER(S19)*S19>L19,"逾期完成",ISNUMBER(S19),"按期完成",L19>TODAY(),"待完成","逾期未完成")} -> 按期完成 | AB19: {=_xlfn.SWITCH(TRUE,ISNUMBER(T19)*T19>M19,"逾期完成",ISNUMBER(T19),"按期完成",M19>TODAY(),"待完成","逾期未完成")} -> 逾期完成 | AC19: {=_xlfn.SWITCH(TRUE,ISNUMBER(U19)*U19>N19,"逾期完成",ISNUMBER(U19),"按期完成",N19>TODAY(),"待完成","逾期未完成")} -> 逾期未完成 | AD19: {=_xlfn.SWITCH(TRUE,ISNUMBER(V19)*V19>O19,"逾期完成",ISNUMBER(V19),"按期完成",O19>TODAY(),"待完成","逾期未完成")} -> 逾期未完成 | AE19: =IF(ISNUMBER(X19),"已获证","未获证") -> 已获证 | AF19: {=_xlfn.SWITCH(TRUE,ISNUMBER(W19)*W19>P19,"逾期完成",ISNUMBER(W19),"按期完成",P19>TODAY(),"待完成","逾期未完成")} -> 逾期未完成 | AG19: 未完成 | AJ19: 低 | AK19: 纪鹏飞 | AL19: 自研 | AM19: =IF(AND(OR(AB19="按期完成",AB19="逾期完成"),OR(AC19<>"待完成",AD19<>"待完成")),"批产,"&IF(OR(AC19="逾期完成",AC19="逾期未完成",AD19="逾期完成",AD19="逾期未完成"),"逾期","按期"),IF(AND(OR(Z19="按期完成",Z19="逾期完成"),OR(AA19<>"待完成",AB19<>"待完成")),"中试,"&IF(OR(AA19="逾期完成",AA19="逾期未完成",AB19="逾期完成",AB19="逾期未完成"),"逾期","按期"),IF(OR(Y19<>"待完成",Z19<>"待完成"),"送检,"&IF(OR(Y19="逾期完成",Y19="逾期未完成",Z19="逾期完成",Z19="逾期未完成"),"逾期","按期"),"未启动,未开始"))) -> 批产,逾期 | AN19: =IF(OR(NOT(ISNUMBER(J19)),NOT(ISNUMBER(L19)),NOT(ISNUMBER(M19)),NOT(ISNUMBER(N19)),NOT(ISNUMBER(O19)),NOT(ISNUMBER(P19))),"暂无计划",IF(ISBLANK(Q19),IF(AND(J19-TODAY()>=0,J19-TODAY()<=10),"⚠️ 送检开始（还有"&ROUNDUP(J19-TODAY(),0)&"天，重点关注）",IF(J19>=TODAY(),"送检开始（还有"&ROUNDUP(J19-TODAY(),0)&"天）","送检开始（已超期"&ROUNDUP(TODAY()-J19,0)&"天）")),IF(ISBLANK(S19),IF(AND(L19-TODAY()>=0,L19-TODAY()<=10),"⚠️ 中试开始（还有"&ROUNDUP(L19-TODAY(),0)&"天，重点关注）",IF(L19>=TODAY(),"中试开始（还有"&ROUNDUP(L19-TODAY(),0)&"天）","中试开始（已超期"&ROUNDUP(TODAY()-L19,0)&"天）")),IF(ISBLANK(T19),IF(AND(M19-TODAY()>=0,M19-TODAY()<=10),"⚠️ 中试结束（还有"&ROUNDUP(M19-TODAY(),0)&"天，重点关注）",IF(M19>=TODAY(),"中试结束（还有"&ROUNDUP(M19-TODAY(),0)&"天）","中试结束（已超期"&ROUNDUP(TODAY()-M19,0)&"天）")),IF(ISBLANK(U19),IF(AND(N19-TODAY()>=0,N19-TODAY()<=10),"⚠️ 批产开始（还有"&ROUNDUP(N19-TODAY(),0)&"天，重点关注）",IF(N19>=TODAY(),"批产开始（还有"&ROUNDUP(N19-TODAY(),0)&"天）","批产开始（已超期"&ROUNDUP(TODAY()-N19,0)&"天）")),IF(ISBLANK(V19),IF(AND(O19-TODAY()>=0,O19-TODAY()<=10),"⚠️ 批产结束（还有"&ROUNDUP(O19-TODAY(),0)&"天，重点关注）",IF(O19>=TODAY(),"批产结束（还有"&ROUNDUP(O19-TODAY(),0)&"天）","批产结束（已超期"&ROUNDUP(TODAY()-O19,0)&"天）")),IF(ISBLANK(W19),IF(AND(P19-TODAY()>=0,P19-TODAY()<=10),"⚠️ 上市（还有"&ROUNDUP(P19-TODAY(),0)&"天，重点关注）",IF(P19>=TODAY(),"上市（还有"&ROUNDUP(P19-TODAY(),0)&"天）","上市（已超期"&ROUNDUP(TODAY()-P19,0)&"天）")),"已完成所有阶段"))))))) -> 批产开始（已超期77天）
A20: 46 | B20: 智能疏散 | C20: 10401549 | E20: 应急照明集中电源（新标） | F20: EI-D-AC(0.5kVA)-T1L01 | G20: 1 | H20: - | I20: - | J20: 45981 | K20: 46063 | L20: 46042 | M20: 46073 | N20: 46073 | O20: =P20 -> 46143 | P20: 46143 | Q20: 45975 | R20: 46055 | S20: 46048 | T20: 46058 | X20: 46083 | Y20: {=_xlfn.SWITCH(TRUE,ISNUMBER(Q20)*Q20>J20,"逾期完成",ISNUMBER(Q20),"按期完成",J20>TODAY(),"待完成","逾期未完成")} -> 按期完成 | Z20: {=_xlfn.SWITCH(TRUE,ISNUMBER(R20)*R20>K20,"逾期完成",ISNUMBER(R20),"按期完成",K20>TODAY(),"待完成","逾期未完成")} -> 按期完成 | AA20: {=_xlfn.SWITCH(TRUE,ISNUMBER(S20)*S20>L20,"逾期完成",ISNUMBER(S20),"按期完成",L20>TODAY(),"待完成","逾期未完成")} -> 逾期完成 | AB20: {=_xlfn.SWITCH(TRUE,ISNUMBER(T20)*T20>M20,"逾期完成",ISNUMBER(T20),"按期完成",M20>TODAY(),"待完成","逾期未完成")} -> 按期完成 | AC20: {=_xlfn.SWITCH(TRUE,ISNUMBER(U20)*U20>N20,"逾期完成",ISNUMBER(U20),"按期完成",N20>TODAY(),"待完成","逾期未完成")} -> 逾期未完成 | AD20: {=_xlfn.SWITCH(TRUE,ISNUMBER(V20)*V20>O20,"逾期完成",ISNUMBER(V20),"按期完成",O20>TODAY(),"待完成","逾期未完成")} -> 逾期未完成 | AE20: =IF(ISNUMBER(X20),"已获证","未获证") -> 已获证 | AF20: {=_xlfn.SWITCH(TRUE,ISNUMBER(W20)*W20>P20,"逾期完成",ISNUMBER(W20),"按期完成",P20>TODAY(),"待完成","逾期未完成")} -> 逾期未完成 | AG20: 完成 | AJ20: 低 | AK20: 敖翔 | AL20: 自研 | AM20: =IF(AND(OR(AB20="按期完成",AB20="逾期完成"),OR(AC20<>"待完成",AD20<>"待完成")),"批产,"&IF(OR(AC20="逾期完成",AC20="逾期未完成",AD20="逾期完成",AD20="逾期未完成"),"逾期","按期"),IF(AND(OR(Z20="按期完成",Z20="逾期完成"),OR(AA20<>"待完成",AB20<>"待完成")),"中试,"&IF(OR(AA20="逾期完成",AA20="逾期未完成",AB20="逾期完成",AB20="逾期未完成"),"逾期","按期"),IF(OR(Y20<>"待完成",Z20<>"待完成"),"送检,"&IF(OR(Y20="逾期完成",Y20="逾期未完成",Z20="逾期完成",Z20="逾期未完成"),"逾期","按期"),"未启动,未开始"))) -> 批产,逾期 | AN20: =IF(OR(NOT(ISNUMBER(J20)),NOT(ISNUMBER(L20)),NOT(ISNUMBER(M20)),NOT(ISNUMBER(N20)),NOT(ISNUMBER(O20)),NOT(ISNUMBER(P20))),"暂无计划",IF(ISBLANK(Q20),IF(AND(J20-TODAY()>=0,J20-TODAY()<=10),"⚠️ 送检开始（还有"&ROUNDUP(J20-TODAY(),0)&"天，重点关注）",IF(J20>=TODAY(),"送检开始（还有"&ROUNDUP(J20-TODAY(),0)&"天）","送检开始（已超期"&ROUNDUP(TODAY()-J20,0)&"天）")),IF(ISBLANK(S20),IF(AND(L20-TODAY()>=0,L20-TODAY()<=10),"⚠️ 中试开始（还有"&ROUNDUP(L20-TODAY(),0)&"天，重点关注）",IF(L20>=TODAY(),"中试开始（还有"&ROUNDUP(L20-TODAY(),0)&"天）","中试开始（已超期"&ROUNDUP(TODAY()-L20,0)&"天）")),IF(ISBLANK(T20),IF(AND(M20-TODAY()>=0,M20-TODAY()<=10),"⚠️ 中试结束（还有"&ROUNDUP(M20-TODAY(),0)&"天，重点关注）",IF(M20>=TODAY(),"中试结束（还有"&ROUNDUP(M20-TODAY(),0)&"天）","中试结束（已超期"&ROUNDUP(TODAY()-M20,0)&"天）")),IF(ISBLANK(U20),IF(AND(N20-TODAY()>=0,N20-TODAY()<=10),"⚠️ 批产开始（还有"&ROUNDUP(N20-TODAY(),0)&"天，重点关注）",IF(N20>=TODAY(),"批产开始（还有"&ROUNDUP(N20-TODAY(),0)&"天）","批产开始（已超期"&ROUNDUP(TODAY()-N20,0)&"天）")),IF(ISBLANK(V20),IF(AND(O20-TODAY()>=0,O20-TODAY()<=10),"⚠️ 批产结束（还有"&ROUNDUP(O20-TODAY(),0)&"天，重点关注）",IF(O20>=TODAY(),"批产结束（还有"&ROUNDUP(O20-TODAY(),0)&"天）","批产结束（已超期"&ROUNDUP(TODAY()-O20,0)&"天）")),IF(ISBLANK(W20),IF(AND(P20-TODAY()>=0,P20-TODAY()<=10),"⚠️ 上市（还有"&ROUNDUP(P20-TODAY(),0)&"天，重点关注）",IF(P20>=TODAY(),"上市（还有"&ROUNDUP(P20-TODAY(),0)&"天）","上市（已超期"&ROUNDUP(TODAY()-P20,0)&"天）")),"已完成所有阶段"))))))) -> 批产开始（已超期105天） | AO20: 45778 | AP20: 46143
A21: 3 | B21: 火灾报警 | C21: 10101244 | E21: 点型感温火灾探测器 | F21: JTW-ZCD-EI9011（新标） | G21: 1 | H21: - | I21: - | J21: 45991 | K21: =(MAX(J21,Q21)+60) -> 46051 | L21: =MAX(J21,Q21)+30 -> 46021 | M21: 46052 | N21: 46054 | O21: =P21 -> 46022 | P21: 46022 | Q21: 45856 | R21: 45940 | S21: 46006 | T21: 46010 | X21: 45971 | Y21: {=_xlfn.SWITCH(TRUE,ISNUMBER(Q21)*Q21>J21,"逾期完成",ISNUMBER(Q21),"按期完成",J21>TODAY(),"待完成","逾期未完成")} -> 按期完成 | Z21: {=_xlfn.SWITCH(TRUE,ISNUMBER(R21)*R21>K21,"逾期完成",ISNUMBER(R21),"按期完成",K21>TODAY(),"待完成","逾期未完成")} -> 按期完成 | AA21: {=_xlfn.SWITCH(TRUE,ISNUMBER(S21)*S21>L21,"逾期完成",ISNUMBER(S21),"按期完成",L21>TODAY(),"待完成","逾期未完成")} -> 按期完成 | AB21: {=_xlfn.SWITCH(TRUE,ISNUMBER(T21)*T21>M21,"逾期完成",ISNUMBER(T21),"按期完成",M21>TODAY(),"待完成","逾期未完成")} -> 按期完成 | AC21: {=_xlfn.SWITCH(TRUE,ISNUMBER(U21)*U21>N21,"逾期完成",ISNUMBER(U21),"按期完成",N21>TODAY(),"待完成","逾期未完成")} -> 逾期未完成 | AD21: {=_xlfn.SWITCH(TRUE,ISNUMBER(V21)*V21>O21,"逾期完成",ISNUMBER(V21),"按期完成",O21>TODAY(),"待完成","逾期未完成")} -> 逾期未完成 | AE21: =IF(ISNUMBER(X21),"已获证","未获证") -> 已获证 | AF21: {=_xlfn.SWITCH(TRUE,ISNUMBER(W21)*W21>P21,"逾期完成",ISNUMBER(W21),"按期完成",P21>TODAY(),"待完成","逾期未完成")} -> 逾期未完成 | AG21: 完成 | AH21: 0 | AJ21: 低 | AK21: 马洪驰 | AL21: 自研 | AM21: =IF(AND(OR(AB21="按期完成",AB21="逾期完成"),OR(AC21<>"待完成",AD21<>"待完成")),"批产,"&IF(OR(AC21="逾期完成",AC21="逾期未完成",AD21="逾期完成",AD21="逾期未完成"),"逾期","按期"),IF(AND(OR(Z21="按期完成",Z21="逾期完成"),OR(AA21<>"待完成",AB21<>"待完成")),"中试,"&IF(OR(AA21="逾期完成",AA21="逾期未完成",AB21="逾期完成",AB21="逾期未完成"),"逾期","按期"),IF(OR(Y21<>"待完成",Z21<>"待完成"),"送检,"&IF(OR(Y21="逾期完成",Y21="逾期未完成",Z21="逾期完成",Z21="逾期未完成"),"逾期","按期"),"未启动,未开始"))) -> 批产,逾期 | AN21: =IF(OR(NOT(ISNUMBER(J21)),NOT(ISNUMBER(L21)),NOT(ISNUMBER(M21)),NOT(ISNUMBER(N21)),NOT(ISNUMBER(O21)),NOT(ISNUMBER(P21))),"暂无计划",IF(ISBLANK(Q21),IF(AND(J21-TODAY()>=0,J21-TODAY()<=10),"⚠️ 送检开始（还有"&ROUNDUP(J21-TODAY(),0)&"天，重点关注）",IF(J21>=TODAY(),"送检开始（还有"&ROUNDUP(J21-TODAY(),0)&"天）","送检开始（已超期"&ROUNDUP(TODAY()-J21,0)&"天）")),IF(ISBLANK(S21),IF(AND(L21-TODAY()>=0,L21-TODAY()<=10),"⚠️ 中试开始（还有"&ROUNDUP(L21-TODAY(),0)&"天，重点关注）",IF(L21>=TODAY(),"中试开始（还有"&ROUNDUP(L21-TODAY(),0)&"天）","中试开始（已超期"&ROUNDUP(TODAY()-L21,0)&"天）")),IF(ISBLANK(T21),IF(AND(M21-TODAY()>=0,M21-TODAY()<=10),"⚠️ 中试结束（还有"&ROUNDUP(M21-TODAY(),0)&"天，重点关注）",IF(M21>=TODAY(),"中试结束（还有"&ROUNDUP(M21-TODAY(),0)&"天）","中试结束（已超期"&ROUNDUP(TODAY()-M21,0)&"天）")),IF(ISBLANK(U21),IF(AND(N21-TODAY()>=0,N21-TODAY()<=10),"⚠️ 批产开始（还有"&ROUNDUP(N21-TODAY(),0)&"天，重点关注）",IF(N21>=TODAY(),"批产开始（还有"&ROUNDUP(N21-TODAY(),0)&"天）","批产开始（已超期"&ROUNDUP(TODAY()-N21,0)&"天）")),IF(ISBLANK(V21),IF(AND(O21-TODAY()>=0,O21-TODAY()<=10),"⚠️ 批产结束（还有"&ROUNDUP(O21-TODAY(),0)&"天，重点关注）",IF(O21>=TODAY(),"批产结束（还有"&ROUNDUP(O21-TODAY(),0)&"天）","批产结束（已超期"&ROUNDUP(TODAY()-O21,0)&"天）")),IF(ISBLANK(W21),IF(AND(P21-TODAY()>=0,P21-TODAY()<=10),"⚠️ 上市（还有"&ROUNDUP(P21-TODAY(),0)&"天，重点关注）",IF(P21>=TODAY(),"上市（还有"&ROUNDUP(P21-TODAY(),0)&"天）","上市（已超期"&ROUNDUP(TODAY()-P21,0)&"天）")),"已完成所有阶段"))))))) -> 批产开始（已超期124天） | AO21: 45992 | AP21: 46357
